Workbook
Name Slicer_有無主板: #N/A
Name Slicer_有無軸承: #N/A
Name Slicer_有無軸承1: #N/A
Name Slicer_傳動比: #N/A
Name Slicer_傳動比1: #N/A
Name Slicer_輪子數: #N/A
Name Slicer_齒輪數量: #N/A
Name Slicer_欄1: #N/A

Sheet 全數據表格
A1: 測試組合 | B1: 傳動比 | C1: 齒輪單雙側傳動 | D1: 齒輪數量 | E1: 輪子數 | F1: 前輪直徑 | G1: 後輪直徑 | H1: 輪子厚度 | I1: 驅動位置 | J1: 有無主板 | K1: 有無軸承 | L1: 負重0g(1) | M1: 負重0g(2) | N1: 負重0g(3) | O1: 負重50g(1) | P1: 負重50g(2) | Q1: 負重100g(1) | R1: 負重100g(2) | S1: 負重150g(1) | T1: 負重150g(2) | U1: 平均值0g | V1: 平均值50g | W1: 平均值100g | X1: 平均值150g | Y1: 有負重平均值 | Z1: 全部平均值 | AA1: 標準差0g | AB1: 標準差50g | AC1: 標準差100g | AD1: 標準差150g | AE1: 有負重標準差平均 | AF1: 全部標準差平均 | AG1: SN ratio 0g | AH1: 全部負重SN ratio | AI1: 完成度 | AJ1: 有負重平均排名 | AK1: 全部平均排名 | AL1: 有負重標準差排名 | AM1: 全部標準差排名 | AN1: 全部SN ratio 排名 | AO1: 綜合排名平均 | AP1: 綜合排名
A2: 1 | B2: 1:1 | C2: 雙 | D2: 3個 | E2: 4輪 | F2: 大(45mm) | G2: 大(45mm) | H2: 單(3.5mm) | I2: 前驅 | J2: 有 | K2: 無 | L2: 732 | M2: 716 | N2: 632 | O2: 557 | P2: 596 | Q2: 562.2 | R2: 500 | S2: 526.5 | T2: 490 | U2: =AVERAGE(L2,M2,N2) -> 693.33333 | V2: =AVERAGE(O2,P2) -> 576.5 | W2: =AVERAGE(Q2,R2) -> 531.1 | X2: =AVERAGE(S2,T2) -> 508.25 | Y2: =AVERAGE(表格14[[#This Row],[負重50g(1)]:[負重150g(2)]]) -> 538.61667 | Z2: =AVERAGE(表格14[[#This Row],[負重0g(1)]:[負重150g(2)]]) -> 590.18889 | AA2: =_xlfn.STDEV.S(表格14[[#This Row],[負重0g(1)]],表格14[[#This Row],[負重0g(2)]],表格14[[#This Row],[負重0g(3)]]) -> 53.715299 | AB2: =_xlfn.STDEV.S(表格14[[#This Row],[負重50g(1)]],表格14[[#This Row],[負重50g(2)]]) -> 27.577164 | AC2: =_xlfn.STDEV.S(表格14[[#This Row],[負重100g(1)]],表格14[[#This Row],[負重100g(2)]]) -> 43.982042 | AD2: =_xlfn.STDEV.S(表格14[[#This Row],[負重150g(1)]],表格14[[#This Row],[負重150g(2)]]) -> 25.809398 | AE2: =AVERAGE(表格14[[#This Row],[標準差50g]:[標準差150g]]) -> 32.456201 | AF2: =AVERAGE(表格14[[#This Row],[標準差0g]:[標準差150g]]) -> 37.770976 | AG2: =-10*LOG10(1/3*((1/表格14[[#This Row],[負重0g(1)]])^2+(1/表格14[[#This Row],[負重0g(2)]])^2+(1/表格14[[#This Row],[負重0g(3)]])^2)) -> 56.763688 | AH2: =-10*LOG10(1/9*((1/$L2)^2+(1/$M2)^2+(1/$N2)^2+(1/$O2)^2+(1/P2)^2+(1/$Q2)^2+(1/$R2)^2+(1/$S2)^2+(1/$T2)^2)) -> 55.181563 | AI2: 0.33333333 | AJ2: =RANK(表格14[[#This Row],[有負重平均值]],表格14[有負重平均值]) -> 22 | AK2: =RANK(表格14[[#This Row],[全部平均值]],表格14[全部平均值]) -> 23 | AL2: =RANK(表格14[[#This Row],[有負重標準差平均]],表格14[有負重標準差平均],1) -> 22 | AM2: =RANK(表格14[[#This Row],[全部標準差平均]],表格14[全部標準差平均],1) -> 20 | AN2: =RANK(表格14[[#This Row],[全部負重SN ratio]],表格14[全部負重SN ratio]) -> 18 | AO2: =AVERAGE(表格14[[#This Row],[有負重平均排名]:[全部SN ratio 排名]]) -> 21 | AP2: =RANK(表格14[[#This Row],[綜合排名平均]],表格14[綜合排名平均],1) -> 25
A3: 2 | B3: 1:1 | C3: 雙 | D3: 3個 | E3: 3輪 | F3: 小(35mm) | G3: 小(35mm) | H3: 雙(7mm) | I3: 前驅 | J3: 有 | K3: 無 | L3: 499 | M3: 536.5 | N3: 506.5 | O3: 540 | P3: 499 | Q3: 481.5 | R3: 489 | S3: 343 | T3: 417 | U3: =AVERAGE(L3,M3,N3) -> 514 | V3: =AVERAGE(O3,P3) -> 519.5 | W3: =AVERAGE(Q3,R3) -> 485.25 | X3: =AVERAGE(S3,T3) -> 380 | Y3: =AVERAGE(表格14[[#This Row],[負重50g(1)]:[負重150g(2)]]) -> 461.58333 | Z3: =AVERAGE(表格14[[#This Row],[負重0g(1)]:[負重150g(2)]]) -> 479.05556 | AA3: =_xlfn.STDEV.S(表格14[[#This Row],[負重0g(1)]],表格14[[#This Row],[負重0g(2)]],表格14[[#This Row],[負重0g(3)]]) -> 19.843135 | AB3: =_xlfn.STDEV.S(表格14[[#This Row],[負重50g(1)]],表格14[[#This Row],[負重50g(2)]]) -> 28.991378 | AC3: =_xlfn.STDEV.S(表格14[[#This Row],[負重100g(1)]],表格14[[#This Row],[負重100g(2)]]) -> 5.3033009 | AD3: =_xlfn.STDEV.S(表格14[[#This Row],[負重150g(1)]],表格14[[#This Row],[負重150g(2)]]) -> 52.325902 | AE3: =AVERAGE(表格14[[#This Row],[標準差50g]:[標準差150g]]) -> 28.873527 | AF3: =AVERAGE(表格14[[#This Row],[標準差0g]:[標準差150g]]) -> 26.615929 | AG3: =-10*LOG10(1/3*((1/表格14[[#This Row],[負重0g(1)]])^2+(1/表格14[[#This Row],[負重0g(2)]])^2+(1/表格14[[#This Row],[負重0g(3)]])^2)) -> 54.206628 | AH3: =-10*LOG10(1/9*((1/$L3)^2+(1/$M3)^2+(1/$N3)^2+(1/$O3)^2+(1/P3)^2+(1/$Q3)^2+(1/$R3)^2+(1/$S3)^2+(1/$T3)^2)) -> 53.353621 | AI3: 0.33333333 | AJ3: =RANK(表格14[[#This Row],[有負重平均值]],表格14[有負重平均值]) -> 27 | AK3: =RANK(表格14[[#This Row],[全部平均值]],表格14[全部平均值]) -> 28 | AL3: =RANK(表格14[[#This Row],[有負重標準差平均]],表格14[有負重標準差平均],1) -> 19 | AM3: =RANK(表格14[[#This Row],[全部標準差平均]],表格14[全部標準差平均],1) -> 14 | AN3: =RANK(表格14[[#This Row],[全部負重SN ratio]],表格14[全部負重SN ratio]) -> 26 | AO3: =AVERAGE(表格14[[#This Row],[有負重平均排名]:[全部SN ratio 排名]]) -> 22.8 | AP3: =RANK(表格14[[#This Row],[綜合排名平均]],表格14[綜合排名平均],1) -> 28
A4: 3 | B4: 1:1 | C4: 雙 | D4: 2個 | E4: 4輪 | F4: 大(45mm) | G4: 小(35mm) | H4: 雙(7mm) | I4: 後驅 | J4: 有 | K4: 無 | L4: 562 | M4: 563.5 | N4: 502 | O4: 458 | P4: 458.5 | Q4: 531 | R4: 484 | S4: 495 | T4: 430 | U4: =AVERAGE(L4,M4,N4) -> 542.5 | V4: =AVERAGE(O4,P4) -> 458.25 | W4: =AVERAGE(Q4,R4) -> 507.5 | X4: =AVERAGE(S4,T4) -> 462.5 | Y4: =AVERAGE(表格14[[#This Row],[負重50g(1)]:[負重150g(2)]]) -> 476.08333 | Z4: =AVERAGE(表格14[[#This Row],[負重0g(1)]:[負重150g(2)]]) -> 498.22222 | AA4: =_xlfn.STDEV.S(表格14[[#This Row],[負重0g(1)]],表格14[[#This Row],[負重0g(2)]],表格14[[#This Row],[負重0g(3)]]) -> 35.082047 | AB4: =_xlfn.STDEV.S(表格14[[#This Row],[負重50g(1)]],表格14[[#This Row],[負重50g(2)]]) -> 0.35355339 | AC4: =_xlfn.STDEV.S(表格14[[#This Row],[負重100g(1)]],表格14[[#This Row],[負重100g(2)]]) -> 33.234019 | AD4: =_xlfn.STDEV.S(表格14[[#This Row],[負重150g(1)]],表格14[[#This Row],[負重150g(2)]]) -> 45.961941 | AE4: =AVERAGE(表格14[[#This Row],[標準差50g]:[標準差150g]]) -> 26.516504 | AF4: =AVERAGE(表格14[[#This Row],[標準差0g]:[標準差150g]]) -> 28.65789 | AG4: =-10*LOG10(1/3*((1/表格14[[#This Row],[負重0g(1)]])^2+(1/表格14[[#This Row],[負重0g(2)]])^2+(1/表格14[[#This Row],[負重0g(3)]])^2)) -> 54.649762 | AH4: =-10*LOG10(1/9*((1/$L4)^2+(1/$M4)^2+(1/$N4)^2+(1/$O4)^2+(1/P4)^2+(1/$Q4)^2+(1/$R4)^2+(1/$S4)^2+(1/$T4)^2)) -> 53.8472 | AI4: 0.88888889 | AJ4: =RANK(表格14[[#This Row],[有負重平均值]],表格14[有負重平均值]) -> 26 | AK4: =RANK(表格14[[#This Row],[全部平均值]],表格14[全部平均值]) -> 27 | AL4: =RANK(表格14[[#This Row],[有負重標準差平均]],表格14[有負重標準差平均],1) -> 15 | AM4: =RANK(表格14[[#This Row],[全部標準差平均]],表格14[全部標準差平均],1) -> 15 | AN4: =RANK(表格14[[#This Row],[全部負重SN ratio]],表格14[全部負重SN ratio]) -> 24 | AO4: =AVERAGE(表格14[[#This Row],[有負重平均排名]:[全部SN ratio 排名]]) -> 21.4 | AP4: =RANK(表格14[[#This Row],[綜合排名平均]],表格14[綜合排名平均],1) -> 27
A5: 4 | B5: 1:1 | C5: 雙 | D5: 2個 | E5: 3輪 | F5: 小(35mm) | G5: 大(45mm) | H5: 單(3.5mm) | I5: 後驅 | J5: 有 | K5: 無 | L5: 756 | M5: 668 | N5: 702.5 | O5: 565 | P5: 572 | Q5: 508 | R5: 503.5 | S5: 489 | T5: 387 | U5: =AVERAGE(L5,M5,N5) -> 708.83333 | V5: =AVERAGE(O5,P5) -> 568.5 | W5: =AVERAGE(Q5,R5) -> 505.75 | X5: =AVERAGE(S5,T5) -> 438 | Y5: =AVERAGE(表格14[[#This Row],[負重50g(1)]:[負重150g(2)]]) -> 504.08333 | Z5: =AVERAGE(表格14[[#This Row],[負重0g(1)]:[負重150g(2)]]) -> 572.33333 | AA5: =_xlfn.STDEV.S(表格14[[#This Row],[負重0g(1)]],表格14[[#This Row],[負重0g(2)]],表格14[[#This Row],[負重0g(3)]]) -> 44.340538 | AB5: =_xlfn.STDEV.S(表格14[[#This Row],[負重50g(1)]],表格14[[#This Row],[負重50g(2)]]) -> 4.9497475 | AC5: =_xlfn.STDEV.S(表格14[[#This Row],[負重100g(1)]],表格14[[#This Row],[負重100g(2)]]) -> 3.1819805 | AD5: =_xlfn.STDEV.S(表格14[[#This Row],[負重150g(1)]],表格14[[#This Row],[負重150g(2)]]) -> 72.124892 | AE5: =AVERAGE(表格14[[#This Row],[標準差50g]:[標準差150g]]) -> 26.752207 | AF5: =AVERAGE(表格14[[#This Row],[標準差0g]:[標準差150g]]) -> 31.149289 | AG5: =-10*LOG10(1/3*((1/表格14[[#This Row],[負重0g(1)]])^2+(1/表格14[[#This Row],[負重0g(2)]])^2+(1/表格14[[#This Row],[負重0g(3)]])^2)) -> 56.977402 | AH5: =-10*LOG10(1/9*((1/$L5)^2+(1/$M5)^2+(1/$N5)^2+(1/$O5)^2+(1/P5)^2+(1/$Q5)^2+(1/$R5)^2+(1/$S5)^2+(1/$T5)^2)) -> 54.645018 | AI5: 0.33333333 | AJ5: =RANK(表格14[[#This Row],[有負重平均值]],表格14[有負重平均值]) -> 23 | AK5: =RANK(表格14[[#This Row],[全部平均值]],表格14[全部平均值]) -> 24 | AL5: =RANK(表格14[[#This Row],[有負重標準差平均]],表格14[有負重標準差平均],1) -> 17 | AM5: =RANK(表格14[[#This Row],[全部標準差平均]],表格14[全部標準差平均],1) -> 16 | AN5: =RANK(表格14[[#This Row],[全部負重SN ratio]],表格14[全部負重SN ratio]) -> 21 | AO5: =AVERAGE(表格14[[#This Row],[有負重平均排名]:[全部SN ratio 排名]]) -> 20.2 | AP5: =RANK(表格14[[#This Row],[綜合排名平均]],表格14[綜合排名平均],1) -> 24
A6: 5 | B6: 1:1 | C6: 單 | D6: 3個 | E6: 4輪 | F6: 小(35mm) | G6: 大(45mm) | H6: 雙(7mm) | I6: 前驅 | J6: 有 | K6: 無 | L6: 627 | M6: 586 | N6: 600 | O6: 487 | P6: 531 | Q6: 463 | R6: 431 | S6: 382 | T6: 391 | U6: =AVERAGE(L6,M6,N6) -> 604.33333 | V6: =AVERAGE(O6,P6) -> 509 | W6: =AVERAGE(Q6,R6) -> 447 | X6: =AVERAGE(S6,T6) -> 386.5 | Y6: =AVERAGE(表格14[[#This Row],[負重50g(1)]:[負重150g(2)]]) -> 447.5 | Z6: =AVERAGE(表格14[[#This Row],[負重0g(1)]:[負重150g(2)]]) -> 499.77778 | AA6: =_xlfn.STDEV.S(表格14[[#This Row],[負重0g(1)]],表格14[[#This Row],[負重0g(2)]],表格14[[#This Row],[負重0g(3)]]) -> 20.840665 | AB6: =_xlfn.STDEV.S(表格14[[#This Row],[負重50g(1)]],表格14[[#This Row],[負重50g(2)]]) -> 31.112698 | AC6: =_xlfn.STDEV.S(表格14[[#This Row],[負重100g(1)]],表格14[[#This Row],[負重100g(2)]]) -> 22.627417 | AD6: =_xlfn.STDEV.S(表格14[[#This Row],[負重150g(1)]],表格14[[#This Row],[負重150g(2)]]) -> 6.363961 | AE6: =AVERAGE(表格14[[#This Row],[標準差50g]:[標準差150g]]) -> 20.034692 | AF6: =AVERAGE(表格14[[#This Row],[標準差0g]:[標準差150g]]) -> 20.236185 | AG6: =-10*LOG10(1/3*((1/表格14[[#This Row],[負重0g(1)]])^2+(1/表格14[[#This Row],[負重0g(2)]])^2+(1/表格14[[#This Row],[負重0g(3)]])^2)) -> 55.615335 | AH6: =-10*LOG10(1/9*((1/$L6)^2+(1/$M6)^2+(1/$N6)^2+(1/$O6)^2+(1/P6)^2+(1/$Q6)^2+(1/$R6)^2+(1/$S6)^2+(1/$T6)^2)) -> 53.583212 | AI6: 0.66666667 | AJ6: =RANK(表格14[[#This Row],[有負重平均值]],表格14[有負重平均值]) -> 28 | AK6: =RANK(表格14[[#This Row],[全部平均值]],表格14[全部平均值]) -> 26 | AL6: =RANK(表格14[[#This Row],[有負重標準差平均]],表格14[有負重標準差平均],1) -> 10 | AM6: =RANK(表格14[[#This Row],[全部標準差平均]],表格14[全部標準差平均],1) -> 6 | AN6: =RANK(表格14[[#This Row],[全部負重SN ratio]],表格14[全部負重SN ratio]) -> 25 | AO6: =AVERAGE(表格14[[#This Row],[有負重平均排名]:[全部SN ratio 排名]]) -> 19 | AP6: =RANK(表格14[[#This Row],[綜合排名平均]],表格14[綜合排名平均],1) -> 20
A7: 6 | B7: 1:1 | C7: 單 | D7: 3個 | E7: 3輪 | F7: 大(45mm) | G7: 小(35mm) | H7: 單(3.5mm) | I7: 前驅 | J7: 有 | K7: 無 | L7: 756 | M7: 531 | N7: 720 | O7: 625 | P7: 723 | Q7: 570.5 | R7: 583 | S7: 505 | T7: 503 | U7: =AVERAGE(L7,M7,N7) -> 669 | V7: =AVERAGE(O7,P7) -> 674 | W7: =AVERAGE(Q7,R7) -> 576.75 | X7: =AVERAGE(S7,T7) -> 504 | Y7: =AVERAGE(表格14[[#This Row],[負重50g(1)]:[負重150g(2)]]) -> 584.91667 | Z7: =AVERAGE(表格14[[#This Row],[負重0g(1)]:[負重150g(2)]]) -> 612.94444 | AA7: =_xlfn.STDEV.S(表格14[[#This Row],[負重0g(1)]],表格14[[#This Row],[負重0g(2)]],表格14[[#This Row],[負重0g(3)]]) -> 120.85942 | AB7: =_xlfn.STDEV.S(表格14[[#This Row],[負重50g(1)]],表格14[[#This Row],[負重50g(2)]]) -> 69.296465 | AC7: =_xlfn.STDEV.S(表格14[[#This Row],[負重100g(1)]],表格14[[#This Row],[負重100g(2)]]) -> 8.8388348 | AD7: =_xlfn.STDEV.S(表格14[[#This Row],[負重150g(1)]],表格14[[#This Row],[負重150g(2)]]) -> 1.4142136 | AE7: =AVERAGE(表格14[[#This Row],[標準差50g]:[標準差150g]]) -> 26.516504 | AF7: =AVERAGE(表格14[[#This Row],[標準差0g]:[標準差150g]]) -> 50.102234 | AG7: =-10*LOG10(1/3*((1/表格14[[#This Row],[負重0g(1)]])^2+(1/表格14[[#This Row],[負重0g(2)]])^2+(1/表格14[[#This Row],[負重0g(3)]])^2)) -> 56.18267 | AH7: =-10*LOG10(1/9*((1/$L7)^2+(1/$M7)^2+(1/$N7)^2+(1/$O7)^2+(1/P7)^2+(1/$Q7)^2+(1/$R7)^2+(1/$S7)^2+(1/$T7)^2)) -> 55.46231 | AI7: 0.66666667 | AJ7: =RANK(表格14[[#This Row],[有負重平均值]],表格14[有負重平均值]) -> 16 | AK7: =RANK(表格14[[#This Row],[全部平均值]],表格14[全部平均值]) -> 22 | AL7: =RANK(表格14[[#This Row],[有負重標準差平均]],表格14[有負重標準差平均],1) -> 15 | AM7: =RANK(表格14[[#This Row],[全部標準差平均]],表格14[全部標準差平均],1) -> 23 | AN7: =RANK(表格14[[#This Row],[全部負重SN ratio]],表格14[全部負重SN ratio]) -> 17 | AO7: =AVERAGE(表格14[[#This Row],[有負重平均排名]:[全部SN ratio 排名]]) -> 18.6 | AP7: =RANK(表格14[[#This Row],[綜合排名平均]],表格14[綜合排名平均],1) -> 19
A8: 7 | B8: 1:1 | C8: 單 | D8: 2個 | E8: 4輪 | F8: 小(35mm) | G8: 小(35mm) | H8: 單(3.5mm) | I8: 後驅 | J8: 有 | K8: 無 | L8: 591 | M8: 599.5 | N8: 583 | O8: 529 | P8: 495 | Q8: 523 | R8: 501 | S8: 456.5 | T8: 491 | U8: =AVERAGE(L8,M8,N8) -> 591.16667 | V8: =AVERAGE(O8,P8) -> 512 | W8: =AVERAGE(Q8,R8) -> 512 | X8: =AVERAGE(S8,T8) -> 473.75 | Y8: =AVERAGE(表格14[[#This Row],[負重50g(1)]:[負重150g(2)]]) -> 499.25 | Z8: =AVERAGE(表格14[[#This Row],[負重0g(1)]:[負重150g(2)]]) -> 529.88889 | AA8: =_xlfn.STDEV.S(表格14[[#This Row],[負重0g(1)]],表格14[[#This Row],[負重0g(2)]],表格14[[#This Row],[負重0g(3)]]) -> 8.2512625 | AB8: =_xlfn.STDEV.S(表格14[[#This Row],[負重50g(1)]],表格14[[#This Row],[負重50g(2)]]) -> 24.041631 | AC8: =_xlfn.STDEV.S(表格14[[#This Row],[負重100g(1)]],表格14[[#This Row],[負重100g(2)]]) -> 15.556349 | AD8: =_xlfn.STDEV.S(表格14[[#This Row],[負重150g(1)]],表格14[[#This Row],[負重150g(2)]]) -> 24.395184 | AE8: =AVERAGE(表格14[[#This Row],[標準差50g]:[標準差150g]]) -> 21.331055 | AF8: =AVERAGE(表格14[[#This Row],[標準差0g]:[標準差150g]]) -> 18.061107 | AG8: =-10*LOG10(1/3*((1/表格14[[#This Row],[負重0g(1)]])^2+(1/表格14[[#This Row],[負重0g(2)]])^2+(1/表格14[[#This Row],[負重0g(3)]])^2)) -> 55.432507 | AH8: =-10*LOG10(1/9*((1/$L8)^2+(1/$M8)^2+(1/$N8)^2+(1/$O8)^2+(1/P8)^2+(1/$Q8)^2+(1/$R8)^2+(1/$S8)^2+(1/$T8)^2)) -> 54.379869 | AI8: 0.66666667 | AJ8: =RANK(表格14[[#This Row],[有負重平均值]],表格14[有負重平均值]) -> 24 | AK8: =RANK(表格14[[#This Row],[全部平均值]],表格14[全部平均值]) -> 25 | AL8: =RANK(表格14[[#This Row],[有負重標準差平均]],表格14[有負重標準差平均],1) -> 12 | AM8: =RANK(表格14[[#This Row],[全部標準差平均]],表格14[全部標準差平均],1) -> 4 | AN8: =RANK(表格14[[#This Row],[全部負重SN ratio]],表格14[全部負重SN ratio]) -> 22 | AO8: =AVERAGE(表格14[[#This Row],[有負重平均排名]:[全部SN ratio 排名]]) -> 17.4 | AP8: =RANK(表格14[[#This Row],[綜合排名平均]],表格14[綜合排名平均],1) -> 17
A9: 8 | B9: 1:1 | C9: 單 | D9: 2個 | E9: 3輪 | F9: 大(45mm) | G9: 大(45mm) | H9: 雙(7mm) | I9: 後驅 | J9: 有 | K9: 無 | L9: 762 | M9: 772 | N9: 743 | O9: 634 | P9: 632 | Q9: 577 | R9: 577.5 | S9: 511.5 | T9: 552.5 | U9: =AVERAGE(L9,M9,N9) -> 759 | V9: =AVERAGE(O9,P9) -> 633 | W9: =AVERAGE(Q9,R9) -> 577.25 | X9: =AVERAGE(S9,T9) -> 532 | Y9: =AVERAGE(表格14[[#This Row],[負重50g(1)]:[負重150g(2)]]) -> 580.75 | Z9: =AVERAGE(表格14[[#This Row],[負重0g(1)]:[負重150g(2)]]) -> 640.16667 | AA9: =_xlfn.STDEV.S(表格14[[#This Row],[負重0g(1)]],表格14[[#This Row],[負重0g(2)]],表格14[[#This Row],[負重0g(3)]]) -> 14.73092 | AB9: =_xlfn.STDEV.S(表格14[[#This Row],[負重50g(1)]],表格14[[#This Row],[負重50g(2)]]) -> 1.4142136 | AC9: =_xlfn.STDEV.S(表格14[[#This Row],[負重100g(1)]],表格14[[#This Row],[負重100g(2)]]) -> 0.35355339 | AD9: =_xlfn.STDEV.S(表格14[[#This Row],[負重150g(1)]],表格14[[#This Row],[負重150g(2)]]) -> 28.991378 | AE9: =AVERAGE(表格14[[#This Row],[標準差50g]:[標準差150g]]) -> 10.253048 | AF9: =AVERAGE(表格14[[#This Row],[標準差0g]:[標準差150g]]) -> 11.372516 | AG9: =-10*LOG10(1/3*((1/表格14[[#This Row],[負重0g(1)]])^2+(1/表格14[[#This Row],[負重0g(2)]])^2+(1/表格14[[#This Row],[負重0g(3)]])^2)) -> 57.601538 | AH9: =-10*LOG10(1/9*((1/$L9)^2+(1/$M9)^2+(1/$N9)^2+(1/$O9)^2+(1/P9)^2+(1/$Q9)^2+(1/$R9)^2+(1/$S9)^2+(1/$T9)^2)) -> 55.868273 | AI9: 0.55555556 | AJ9: =RANK(表格14[[#This Row],[有負重平均值]],表格14[有負重平均值]) -> 18 | AK9: =RANK(表格14[[#This Row],[全部平均值]],表格14[全部平均值]) -> 20 | AL9: =RANK(表格14[[#This Row],[有負重標準差平均]],表格14[有負重標準差平均],1) -> 6 | AM9: =RANK(表格14[[#This Row],[全部標準差平均]],表格14[全部標準差平均],1) -> 2 | AN9: =RANK(表格14[[#This Row],[全部負重SN ratio]],表格14[全部負重SN ratio]) -> 13 | AO9: =AVERAGE(表格14[[#This Row],[有負重平均排名]:[全部SN ratio 排名]]) -> 11.8 | AP9: =RANK(表格14[[#This Row],[綜合排名平均]],表格14[綜合排名平均],1) -> 8
A10: 9 | B10: 1:2 | C10: 雙 | D10: 3個 | E10: 4輪 | F10: 大(45mm) | G10: 大(45mm) | H10: 雙(7mm) | I10: 前驅 | J10: 有 | K10: 無 | L10: 773 | M10: 834 | N10: 858 | O10: 675 | P10: 641 | Q10: 611 | R10: 520 | S10: 514 | T10: 486 | U10: =AVERAGE(L10,M10,N10) -> 821.66667 | V10: =AVERAGE(O10,P10) -> 658 | W10: =AVERAGE(Q10,R10) -> 565.5 | X10: =AVERAGE(S10,T10) -> 500 | Y10: =AVERAGE(表格14[[#This Row],[負重50g(1)]:[負重150g(2)]]) -> 574.5 | Z10: =AVERAGE(表格14[[#This Row],[負重0g(1)]:[負重150g(2)]]) -> 656.88889 | AA10: =_xlfn.STDEV.S(表格14[[#This Row],[負重0g(1)]],表格14[[#This Row],[負重0g(2)]],表格14[[#This Row],[負重0g(3)]]) -> 43.821608 | AB10: =_xlfn.STDEV.S(表格14[[#This Row],[負重50g(1)]],表格14[[#This Row],[負重50g(2)]]) -> 24.041631 | AC10: =_xlfn.STDEV.S(表格14[[#This Row],[負重100g(1)]],表格14[[#This Row],[負重100g(2)]]) -> 64.346717 | AD10: =_xlfn.STDEV.S(表格14[[#This Row],[負重150g(1)]],表格14[[#This Row],[負重150g(2)]]) -> 19.79899 | AE10: =AVERAGE(表格14[[#This Row],[標準差50g]:[標準差150g]]) -> 36.062446 | AF10: =AVERAGE(表格14[[#This Row],[標準差0g]:[標準差150g]]) -> 38.002236 | AG10: =-10*LOG10(1/3*((1/表格14[[#This Row],[負重0g(1)]])^2+(1/表格14[[#This Row],[負重0g(2)]])^2+(1/表格14[[#This Row],[負重0g(3)]])^2)) -> 58.268477 | AH10: =-10*LOG10(1/9*((1/$L10)^2+(1/$M10)^2+(1/$N10)^2+(1/$O10)^2+(1/P10)^2+(1/$Q10)^2+(1/$R10)^2+(1/$S10)^2+(1/$T10)^2)) -> 55.832863 | AI10: 0 | AJ10: =RANK(表格14[[#This Row],[有負重平均值]],表格14[有負重平均值]) -> 19 | AK10: =RANK(表格14[[#This Row],[全部平均值]],表格14[全部平均值]) -> 19 | AL10: =RANK(表格14[[#This Row],[有負重標準差平均]],表格14[有負重標準差平均],1) -> 24 | AM10: =RANK(表格14[[#This Row],[全部標準差平均]],表格14[全部標準差平均],1) -> 21 | AN10: =RANK(表格14[[#This Row],[全部負重SN ratio]],表格14[全部負重SN ratio]) -> 14 | AO10: =AVERAGE(表格14[[#This Row],[有負重平均排名]:[全部SN ratio 排名]]) -> 19.4 | AP10: =RANK(表格14[[#This Row],[綜合排名平均]],表格14[綜合排名平均],1) -> 23
A11: 10 | B11: 1:2 | C11: 雙 | D11: 3個 | E11: 3輪 | F11: 小(35mm) | G11: 小(35mm) | H11: 單(3.5mm) | I11: 前驅 | J11: 有 | K11: 無 | L11: 1088 | M11: 983 | N11: 1010 | O11: 967 | P11: 943.5 | Q11: 578 | R11: 572 | S11: 328 | T11: 348.5 | U11: =AVERAGE(L11,M11,N11) -> 1027 | V11: =AVERAGE(O11,P11) -> 955.25 | W11: =AVERAGE(Q11,R11) -> 575 | X11: =AVERAGE(S11,T11) -> 338.25 | Y11: =AVERAGE(表格14[[#This Row],[負重50g(1)]:[負重150g(2)]]) -> 622.83333 | Z11: =AVERAGE(表格14[[#This Row],[負重0g(1)]:[負重150g(2)]]) -> 757.55556 | AA11: =_xlfn.STDEV.S(表格14[[#This Row],[負重0g(1)]],表格14[[#This Row],[負重0g(2)]],表格14[[#This Row],[負重0g(3)]]) -> 54.525224 | AB11: =_xlfn.STDEV.S(表格14[[#This Row],[負重50g(1)]],表格14[[#This Row],[負重50g(2)]]) -> 16.617009 | AC11: =_xlfn.STDEV.S(表格14[[#This Row],[負重100g(1)]],表格14[[#This Row],[負重100g(2)]]) -> 4.2426407 | AD11: =_xlfn.STDEV.S(表格14[[#This Row],[負重150g(1)]],表格14[[#This Row],[負重150g(2)]]) -> 14.495689 | AE11: =AVERAGE(表格14[[#This Row],[標準差50g]:[標準差150g]]) -> 11.785113 | AF11: =AVERAGE(表格14[[#This Row],[標準差0g]:[標準差150g]]) -> 22.470141 | AG11: =-10*LOG10(1/3*((1/表格14[[#This Row],[負重0g(1)]])^2+(1/表格14[[#This Row],[負重0g(2)]])^2+(1/表格14[[#This Row],[負重0g(3)]])^2)) -> 60.207612 | AH11: =-10*LOG10(1/9*((1/$L11)^2+(1/$M11)^2+(1/$N11)^2+(1/$O11)^2+(1/P11)^2+(1/$Q11)^2+(1/$R11)^2+(1/$S11)^2+(1/$T11)^2)) -> 54.974041 | AI11: 0.55555556 | AJ11: =RANK(表格14[[#This Row],[有負重平均值]],表格14[有負重平均值]) -> 14 | AK11: =RANK(表格14[[#This Row],[全部平均值]],表格14[全部平均值]) -> 14 | AL11: =RANK(表格14[[#This Row],[有負重標準差平均]],表格14[有負重標準差平均],1) -> 7 | AM11: =RANK(表格14[[#This Row],[全部標準差平均]],表格14[全部標準差平均],1) -> 10 | AN11: =RANK(表格14[[#This Row],[全部負重SN ratio]],表格14[全部負重SN ratio]) -> 20 | AO11: =AVERAGE(表格14[[#This Row],[有負重平均排名]:[全部SN ratio 排名]]) -> 13 | AP11: =RANK(表格14[[#This Row],[綜合排名平均]],表格14[綜合排名平均],1) -> 11
A12: 11 | B12: 1:2 | C12: 雙 | D12: 2個 | E12: 4輪 | F12: 大(45mm) | G12: 小(35mm) | H12: 單(3.5mm) | I12: 後驅 | J12: 有 | K12: 無 | L12: 1006 | M12: 1124 | N12: 1132 | O12: 1005 | P12: 991 | Q12: 810 | R12: 623 | S12: 596.5 | T12: 618 | U12: =AVERAGE(L12,M12,N12) -> 1087.3333 | V12: =AVERAGE(O12,P12) -> 998 | W12: =AVERAGE(Q12,R12) -> 716.5 | X12: =AVERAGE(S12,T12) -> 607.25 | Y12: =AVERAGE(表格14[[#This Row],[負重50g(1)]:[負重150g(2)]]) -> 773.91667 | Z12: =AVERAGE(表格14[[#This Row],[負重0g(1)]:[負重150g(2)]]) -> 878.38889 | AA12: =_xlfn.STDEV.S(表格14[[#This Row],[負重0g(1)]],表格14[[#This Row],[負重0g(2)]],表格14[[#This Row],[負重0g(3)]]) -> 70.550219 | AB12: =_xlfn.STDEV.S(表格14[[#This Row],[負重50g(1)]],表格14[[#This Row],[負重50g(2)]]) -> 9.8994949 | AC12: =_xlfn.STDEV.S(表格14[[#This Row],[負重100g(1)]],表格14[[#This Row],[負重100g(2)]]) -> 132.22897 | AD12: =_xlfn.STDEV.S(表格14[[#This Row],[負重150g(1)]],表格14[[#This Row],[負重150g(2)]]) -> 15.202796 | AE12: =AVERAGE(表格14[[#This Row],[標準差50g]:[標準差150g]]) -> 52.443753 | AF12: =AVERAGE(表格14[[#This Row],[標準差0g]:[標準差150g]]) -> 56.970369 | AG12: =-10*LOG10(1/3*((1/表格14[[#This Row],[負重0g(1)]])^2+(1/表格14[[#This Row],[負重0g(2)]])^2+(1/表格14[[#This Row],[負重0g(3)]])^2)) -> 60.688781 | AH12: =-10*LOG10(1/9*((1/$L12)^2+(1/$M12)^2+(1/$N12)^2+(1/$O12)^2+(1/P12)^2+(1/$Q12)^2+(1/$R12)^2+(1/$S12)^2+(1/$T12)^2)) -> 58.050926 | AI12: 0.55555556 | AJ12: =RANK(表格14[[#This Row],[有負重平均值]],表格14[有負重平均值]) -> 4 | AK12: =RANK(表格14[[#This Row],[全部平均值]],表格14[全部平均值]) -> 2 | AL12: =RANK(表格14[[#This Row],[有負重標準差平均]],表格14[有負重標準差平均],1) -> 27 | AM12: =RANK(表格14[[#This Row],[全部標準差平均]],表格14[全部標準差平均],1) -> 25 | AN12: =RANK(表格14[[#This Row],[全部負重SN ratio]],表格14[全部負重SN ratio]) -> 5 | AO12: =AVERAGE(表格14[[#This Row],[有負重平均排名]:[全部SN ratio 排名]]) -> 12.6 | AP12: =RANK(表格14[[#This Row],[綜合排名平均]],表格14[綜合排名平均],1) -> 10
A13: 12 | B13: 1:2 | C13: 雙 | D13: 2個 | E13: 3輪 | F13: 小(35mm) | G13: 大(45mm) | H13: 雙(7mm) | I13: 後驅 | J13: 有 | K13: 無 | L13: 1337 | M13: 1295 | N13: 989 | O13: 497 | P13: 528 | Q13: 475 | R13: 467 | S13: 454 | T13: 469 | U13: =AVERAGE(L13,M13,N13) -> 1207 | V13: =AVERAGE(O13,P13) -> 512.5 | W13: =AVERAGE(Q13,R13) -> 471 | X13: =AVERAGE(S13,T13) -> 461.5 | Y13: =AVERAGE(表格14[[#This Row],[負重50g(1)]:[負重150g(2)]]) -> 481.66667 | Z13: =AVERAGE(表格14[[#This Row],[負重0g(1)]:[負重150g(2)]]) -> 723.44444 | AA13: =_xlfn.STDEV.S(表格14[[#This Row],[負重0g(1)]],表格14[[#This Row],[負重0g(2)]],表格14[[#This Row],[負重0g(3)]]) -> 189.95789 | AB13: =_xlfn.STDEV.S(表格14[[#This Row],[負重50g(1)]],表格14[[#This Row],[負重50g(2)]]) -> 21.92031 | AC13: =_xlfn.STDEV.S(表格14[[#This Row],[負重100g(1)]],表格14[[#This Row],[負重100g(2)]]) -> 5.6568542 | AD13: =_xlfn.STDEV.S(表格14[[#This Row],[負重150g(1)]],表格14[[#This Row],[負重150g(2)]]) -> 10.606602 | AE13: =AVERAGE(表格14[[#This Row],[標準差50g]:[標準差150g]]) -> 12.727922 | AF13: =AVERAGE(表格14[[#This Row],[標準差0g]:[標準差150g]]) -> 57.035414 | AG13: =-10*LOG10(1/3*((1/表格14[[#This Row],[負重0g(1)]])^2+(1/表格14[[#This Row],[負重0g(2)]])^2+(1/表格14[[#This Row],[負重0g(3)]])^2)) -> 61.390471 | AH13: =-10*LOG10(1/9*((1/$L13)^2+(1/$M13)^2+(1/$N13)^2+(1/$O13)^2+(1/P13)^2+(1/$Q13)^2+(1/$R13)^2+(1/$S13)^2+(1/$T13)^2)) -> 55.035495 | AI13: 0.22222222 | AJ13: =RANK(表格14[[#This Row],[有負重平均值]],表格14[有負重平均值]) -> 25 | AK13: =RANK(表格14[[#This Row],[全部平均值]],表格14[全部平均值]) -> 17 | AL13: =RANK(表格14[[#This Row],[有負重標準差平均]],表格14[有負重標準差平均],1) -> 8 | AM13: =RANK(表格14[[#This Row],[全部標準差平均]],表格14[全部標準差平均],1) -> 26 | AN13: =RANK(表格14[[#This Row],[全部負重SN ratio]],表格14[全部負重SN ratio]) -> 19 | AO13: =AVERAGE(表格14[[#This Row],[有負重平均排名]:[全部SN ratio 排名]]) -> 19 | AP13: =RANK(表格14[[#This Row],[綜合排名平均]],表格14[綜合排名平均],1) -> 20
... A24: 23 | B24: 無齒輪 | C24: 無齒輪 | D24: 無齒輪 | E24: 4輪 | F24: 大(45mm) | G24: 大(45mm) | H24: 單(3.5mm) | I24: 前驅 | J24: 無 | K24: 無 | L24: 1107 | M24: 1157 | N24: 1127 | O24: 854 | P24: 811 | Q24: 765 | R24: 713 | S24: 700 | T24: 698 | U24: =AVERAGE(L24,M24,N24) -> 1130.3333 | V24: =AVERAGE(O24,P24) -> 832.5 | W24: =AVERAGE(Q24,R24) -> 739 | X24: =AVERAGE(S24,T24) -> 699 | Y24: =AVERAGE(表格14[[#This Row],[負重50g(1)]:[負重150g(2)]]) -> 756.83333 | Z24: =AVERAGE(表格14[[#This Row],[負重0g(1)]:[負重150g(2)]]) -> 881.33333 | AA24: =_xlfn.STDEV.S(表格14[[#This Row],[負重0g(1)]],表格14[[#This Row],[負重0g(2)]],表格14[[#This Row],[負重0g(3)]]) -> 25.166115 | AB24: =_xlfn.STDEV.S(表格14[[#This Row],[負重50g(1)]],表格14[[#This Row],[負重50g(2)]]) -> 30.405592 | AC24: =_xlfn.STDEV.S(表格14[[#This Row],[負重100g(1)]],表格14[[#This Row],[負重100g(2)]]) -> 36.769553 | AD24: =_xlfn.STDEV.S(表格14[[#This Row],[負重150g(1)]],表格14[[#This Row],[負重150g(2)]]) -> 1.4142136 | AE24: =AVERAGE(表格14[[#This Row],[標準差50g]:[標準差150g]]) -> 22.863119 | AF24: =AVERAGE(表格14[[#This Row],[標準差0g]:[標準差150g]]) -> 23.438868 | AG24: =-10*LOG10(1/3*((1/表格14[[#This Row],[負重0g(1)]])^2+(1/表格14[[#This Row],[負重0g(2)]])^2+(1/表格14[[#This Row],[負重0g(3)]])^2)) -> 61.059849 | AH24: =-10*LOG10(1/9*((1/$L24)^2+(1/$M24)^2+(1/$N24)^2+(1/$O24)^2+(1/P24)^2+(1/$Q24)^2+(1/$R24)^2+(1/$S24)^2+(1/$T24)^2)) -> 58.39929 | AI24: 1 | AJ24: =RANK(表格14[[#This Row],[有負重平均值]],表格14[有負重平均值]) -> 5 | AK24: =RANK(表格14[[#This Row],[全部平均值]],表格14[全部平均值]) -> 1 | AL24: =RANK(表格14[[#This Row],[有負重標準差平均]],表格14[有負重標準差平均],1) -> 13 | AM24: =RANK(表格14[[#This Row],[全部標準差平均]],表格14[全部標準差平均],1) -> 12 | AN24: =RANK(表格14[[#This Row],[全部負重SN ratio]],表格14[全部負重SN ratio]) -> 3 | AO24: =AVERAGE(表格14[[#This Row],[有負重平均排名]:[全部SN ratio 排名]]) -> 6.8 | AP24: =RANK(表格14[[#This Row],[綜合排名平均]],表格14[綜合排名平均],1) -> 4
A25: 24 | B25: 1:2 | C25: 單 | D25: 2個 | E25: 4輪 | F25: 大(45mm) | G25: 大(45mm) | H25: 單(3.5mm) | I25: 後驅 | J25: 無 | K25: 無 | L25: 1280 | M25: 1268 | N25: 1270 | O25: 706 | P25: 700 | Q25: 500 | R25: 505 | S25: 442 | T25: 420 | U25: =AVERAGE(L25,M25,N25) -> 1272.6667 | V25: =AVERAGE(O25,P25) -> 703 | W25: =AVERAGE(Q25,R25) -> 502.5 | X25: =AVERAGE(S25,T25) -> 431 | Y25: =AVERAGE(表格14[[#This Row],[負重50g(1)]:[負重150g(2)]]) -> 545.5 | Z25: =AVERAGE(表格14[[#This Row],[負重0g(1)]:[負重150g(2)]]) -> 787.88889 | AA25: =_xlfn.STDEV.S(表格14[[#This Row],[負重0g(1)]],表格14[[#This Row],[負重0g(2)]],表格14[[#This Row],[負重0g(3)]]) -> 6.4291005 | AB25: =_xlfn.STDEV.S(表格14[[#This Row],[負重50g(1)]],表格14[[#This Row],[負重50g(2)]]) -> 4.2426407 | AC25: =_xlfn.STDEV.S(表格14[[#This Row],[負重100g(1)]],表格14[[#This Row],[負重100g(2)]]) -> 3.5355339 | AD25: =_xlfn.STDEV.S(表格14[[#This Row],[負重150g(1)]],表格14[[#This Row],[負重150g(2)]]) -> 15.556349 | AE25: =AVERAGE(表格14[[#This Row],[標準差50g]:[標準差150g]]) -> 7.7781746 | AF25: =AVERAGE(表格14[[#This Row],[標準差0g]:[標準差150g]]) -> 7.4409061 | AG25: =-10*LOG10(1/3*((1/表格14[[#This Row],[負重0g(1)]])^2+(1/表格14[[#This Row],[負重0g(2)]])^2+(1/表格14[[#This Row],[負重0g(3)]])^2)) -> 62.094072 | AH25: =-10*LOG10(1/9*((1/$L25)^2+(1/$M25)^2+(1/$N25)^2+(1/$O25)^2+(1/P25)^2+(1/$Q25)^2+(1/$R25)^2+(1/$S25)^2+(1/$T25)^2)) -> 55.631632 | AI25: =3/9 -> 0.33333333 | AJ25: =RANK(表格14[[#This Row],[有負重平均值]],表格14[有負重平均值]) -> 21 | AK25: =RANK(表格14[[#This Row],[全部平均值]],表格14[全部平均值]) -> 12 | AL25: =RANK(表格14[[#This Row],[有負重標準差平均]],表格14[有負重標準差平均],1) -> 3 | AM25: =RANK(表格14[[#This Row],[全部標準差平均]],表格14[全部標準差平均],1) -> 1 | AN25: =RANK(表格14[[#This Row],[全部負重SN ratio]],表格14[全部負重SN ratio]) -> 15 | AO25: =AVERAGE(表格14[[#This Row],[有負重平均排名]:[全部SN ratio 排名]]) -> 10.4 | AP25: =RANK(表格14[[#This Row],[綜合排名平均]],表格14[綜合排名平均],1) -> 7
A26: 25 | B26: 無齒輪 | C26: 無齒輪 | D26: 無齒輪 | E26: 4輪 | F26: 大(45mm) | G26: 大(45mm) | H26: 單(3.5mm) | I26: 前驅 | J26: 無 | K26: 有 | L26: 887 | M26: 880 | N26: 987 | O26: 789 | P26: 775 | Q26: 900 | R26: 918 | S26: 875 | T26: 880 | U26: =AVERAGE(L26,M26,N26) -> 918 | V26: =AVERAGE(O26,P26) -> 782 | W26: =AVERAGE(Q26,R26) -> 909 | X26: =AVERAGE(S26,T26) -> 877.5 | Y26: =AVERAGE(表格14[[#This Row],[負重50g(1)]:[負重150g(2)]]) -> 856.16667 | Z26: =AVERAGE(表格14[[#This Row],[負重0g(1)]:[負重150g(2)]]) -> 876.77778 | AA26: =_xlfn.STDEV.S(表格14[[#This Row],[負重0g(1)]],表格14[[#This Row],[負重0g(2)]],表格14[[#This Row],[負重0g(3)]]) -> 59.858166 | AB26: =_xlfn.STDEV.S(表格14[[#This Row],[負重50g(1)]],表格14[[#This Row],[負重50g(2)]]) -> 9.8994949 | AC26: =_xlfn.STDEV.S(表格14[[#This Row],[負重100g(1)]],表格14[[#This Row],[負重100g(2)]]) -> 12.727922 | AD26: =_xlfn.STDEV.S(表格14[[#This Row],[負重150g(1)]],表格14[[#This Row],[負重150g(2)]]) -> 3.5355339 | AE26: =AVERAGE(表格14[[#This Row],[標準差50g]:[標準差150g]]) -> 8.7209836 | AF26: =AVERAGE(表格14[[#This Row],[標準差0g]:[標準差150g]]) -> 21.505279 | AG26: =-10*LOG10(1/3*((1/表格14[[#This Row],[負重0g(1)]])^2+(1/表格14[[#This Row],[負重0g(2)]])^2+(1/表格14[[#This Row],[負重0g(3)]])^2)) -> 59.221648 | AH26: =-10*LOG10(1/9*((1/$L26)^2+(1/$M26)^2+(1/$N26)^2+(1/$O26)^2+(1/P26)^2+(1/$Q26)^2+(1/$R26)^2+(1/$S26)^2+(1/$T26)^2)) -> 58.794698 | AI26: 1 | AJ26: =RANK(表格14[[#This Row],[有負重平均值]],表格14[有負重平均值]) -> 1 | AK26: =RANK(表格14[[#This Row],[全部平均值]],表格14[全部平均值]) -> 3 | AL26: =RANK(表格14[[#This Row],[有負重標準差平均]],表格14[有負重標準差平均],1) -> 4 | AM26: =RANK(表格14[[#This Row],[全部標準差平均]],表格14[全部標準差平均],1) -> 8 | AN26: =RANK(表格14[[#This Row],[全部負重SN ratio]],表格14[全部負重SN ratio]) -> 1 | AO26: =AVERAGE(表格14[[#This Row],[有負重平均排名]:[全部SN ratio 排名]]) -> 3.4 | AP26: =RANK(表格14[[#This Row],[綜合排名平均]],表格14[綜合排名平均],1) -> 1
A27: 26 | B27: 1:2 | C27: 單 | D27: 2個 | E27: 4輪 | F27: 大(45mm) | G27: 大(45mm) | H27: 單(3.5mm) | I27: 後驅 | J27: 無 | K27: 有 | L27: 910 | M27: 980 | N27: 1002 | O27: 745 | P27: 830 | Q27: 740 | R27: 680 | S27: 670 | T27: 720 | U27: =AVERAGE(L27,M27,N27) -> 964 | V27: =AVERAGE(O27,P27) -> 787.5 | W27: =AVERAGE(Q27,R27) -> 710 | X27: =AVERAGE(S27,T27) -> 695 | Y27: =AVERAGE(表格14[[#This Row],[負重50g(1)]:[負重150g(2)]]) -> 730.83333 | Z27: =AVERAGE(表格14[[#This Row],[負重0g(1)]:[負重150g(2)]]) -> 808.55556 | AA27: =_xlfn.STDEV.S(表格14[[#This Row],[負重0g(1)]],表格14[[#This Row],[負重0g(2)]],表格14[[#This Row],[負重0g(3)]]) -> 48.041649 | AB27: =_xlfn.STDEV.S(表格14[[#This Row],[負重50g(1)]],表格14[[#This Row],[負重50g(2)]]) -> 60.104076 | AC27: =_xlfn.STDEV.S(表格14[[#This Row],[負重100g(1)]],表格14[[#This Row],[負重100g(2)]]) -> 42.426407 | AD27: =_xlfn.STDEV.S(表格14[[#This Row],[負重150g(1)]],表格14[[#This Row],[負重150g(2)]]) -> 35.355339 | AE27: =AVERAGE(表格14[[#This Row],[標準差50g]:[標準差150g]]) -> 45.961941 | AF27: =AVERAGE(表格14[[#This Row],[標準差0g]:[標準差150g]]) -> 46.481868 | AG27: =-10*LOG10(1/3*((1/表格14[[#This Row],[負重0g(1)]])^2+(1/表格14[[#This Row],[負重0g(2)]])^2+(1/表格14[[#This Row],[負重0g(3)]])^2)) -> 59.659295 | AH27: =-10*LOG10(1/9*((1/$L27)^2+(1/$M27)^2+(1/$N27)^2+(1/$O27)^2+(1/P27)^2+(1/$Q27)^2+(1/$R27)^2+(1/$S27)^2+(1/$T27)^2)) -> 57.885947 | AI27: 0 | AJ27: =RANK(表格14[[#This Row],[有負重平均值]],表格14[有負重平均值]) -> 7 | AK27: =RANK(表格14[[#This Row],[全部平均值]],表格14[全部平均值]) -> 8 | AL27: =RANK(表格14[[#This Row],[有負重標準差平均]],表格14[有負重標準差平均],1) -> 26 | AM27: =RANK(表格14[[#This Row],[全部標準差平均]],表格14[全部標準差平均],1) -> 22 | AN27: =RANK(表格14[[#This Row],[全部負重SN ratio]],表格14[全部負重SN ratio]) -> 6 | AO27: =AVERAGE(表格14[[#This Row],[有負重平均排名]:[全部SN ratio 排名]]) -> 13.8 | AP27: =RANK(表格14[[#This Row],[綜合排名平均]],表格14[綜合排名平均],1) -> 14
A28: 27 | B28: 無齒輪 | C28: 無齒輪 | D28: 無齒輪 | E28: 4輪 | F28: 大(45mm) | G28: 大(45mm) | H28: 單(3.5mm) | I28: 前驅 | J28: 有 | K28: 有 | L28: 883 | M28: 877 | N28: 887 | O28: 820 | P28: 830 | Q28: 872 | R28: 818 | S28: 875 | T28: 816 | U28: =AVERAGE(L28,M28,N28) -> 882.33333 | V28: =AVERAGE(O28,P28) -> 825 | W28: =AVERAGE(Q28,R28) -> 845 | X28: =AVERAGE(S28,T28) -> 845.5 | Y28: =AVERAGE(表格14[[#This Row],[負重50g(1)]:[負重150g(2)]]) -> 838.5 | Z28: =AVERAGE(表格14[[#This Row],[負重0g(1)]:[負重150g(2)]]) -> 853.11111 | AA28: =_xlfn.STDEV.S(表格14[[#This Row],[負重0g(1)]],表格14[[#This Row],[負重0g(2)]],表格14[[#This Row],[負重0g(3)]]) -> 5.033223 | AB28: =_xlfn.STDEV.S(表格14[[#This Row],[負重50g(1)]],表格14[[#This Row],[負重50g(2)]]) -> 7.0710678 | AC28: =_xlfn.STDEV.S(表格14[[#This Row],[負重100g(1)]],表格14[[#This Row],[負重100g(2)]]) -> 38.183766 | AD28: =_xlfn.STDEV.S(表格14[[#This Row],[負重150g(1)]],表格14[[#This Row],[負重150g(2)]]) -> 41.7193 | AE28: =AVERAGE(表格14[[#This Row],[標準差50g]:[標準差150g]]) -> 28.991378 | AF28: =AVERAGE(表格14[[#This Row],[標準差0g]:[標準差150g]]) -> 23.001839 | AG28: =-10*LOG10(1/3*((1/表格14[[#This Row],[負重0g(1)]])^2+(1/表格14[[#This Row],[負重0g(2)]])^2+(1/表格14[[#This Row],[負重0g(3)]])^2)) -> 58.912371 | AH28: =AVERAGE(AB28:AF28) -> 27.79347 | AI28: 1 | AJ28: =RANK(表格14[[#This Row],[有負重平均值]],表格14[有負重平均值]) -> 2 | AK28: =RANK(表格14[[#This Row],[全部平均值]],表格14[全部平均值]) -> 5 | AL28: =RANK(表格14[[#This Row],[有負重標準差平均]],表格14[有負重標準差平均],1) -> 20 | AM28: =RANK(表格14[[#This Row],[全部標準差平均]],表格14[全部標準差平均],1) -> 11 | AN28: =RANK(表格14[[#This Row],[全部負重SN ratio]],表格14[全部負重SN ratio]) -> 28 | AO28: =AVERAGE(表格14[[#This Row],[有負重平均排名]:[全部SN ratio 排名]]) -> 13.2 | AP28: =RANK(表格14[[#This Row],[綜合排名平均]],表格14[綜合排名平均],1) -> 12
A29: 28 | B29: 1:2 | C29: 單 | D29: 2個 | E29: 4輪 | F29: 大(45mm) | G29: 大(45mm) | H29: 單(3.5mm) | I29: 後驅 | J29: 有 | K29: 有 | L29: 1000 | M29: 948 | N29: 980 | O29: 892 | P29: 920 | Q29: 572 | R29: 505 | S29: 440 | T29: 487 | U29: =AVERAGE(L29,M29,N29) -> 976 | V29: =AVERAGE(O29,P29) -> 906 | W29: =AVERAGE(Q29,R29) -> 538.5 | X29: =AVERAGE(S29,T29) -> 463.5 | Y29: =AVERAGE(表格14[[#This Row],[負重50g(1)]:[負重150g(2)]]) -> 636 | Z29: =AVERAGE(表格14[[#This Row],[負重0g(1)]:[負重150g(2)]]) -> 749.33333 | AA29: =_xlfn.STDEV.S(表格14[[#This Row],[負重0g(1)]],表格14[[#This Row],[負重0g(2)]],表格14[[#This Row],[負重0g(3)]]) -> 26.229754 | AB29: =_xlfn.STDEV.S(表格14[[#This Row],[負重50g(1)]],表格14[[#This Row],[負重50g(2)]]) -> 19.79899 | AC29: =_xlfn.STDEV.S(表格14[[#This Row],[負重100g(1)]],表格14[[#This Row],[負重100g(2)]]) -> 47.376154 | AD29: =_xlfn.STDEV.S(表格14[[#This Row],[負重150g(1)]],表格14[[#This Row],[負重150g(2)]]) -> 33.234019 | AE29: =AVERAGE(表格14[[#This Row],[標準差50g]:[標準差150g]]) -> 33.469721 | AF29: =AVERAGE(表格14[[#This Row],[標準差0g]:[標準差150g]]) -> 31.659729 | AG29: =-10*LOG10(1/3*((1/表格14[[#This Row],[負重0g(1)]])^2+(1/表格14[[#This Row],[負重0g(2)]])^2+(1/表格14[[#This Row],[負重0g(3)]])^2)) -> 59.78267 | AH29: =AVERAGE(AB29:AF29) -> 33.107723 | AI29: 0 | AJ29: =RANK(表格14[[#This Row],[有負重平均值]],表格14[有負重平均值]) -> 12 | AK29: =RANK(表格14[[#This Row],[全部平均值]],表格14[全部平均值]) -> 16 | AL29: =RANK(表格14[[#This Row],[有負重標準差平均]],表格14[有負重標準差平均],1) -> 23 | AM29: =RANK(表格14[[#This Row],[全部標準差平均]],表格14[全部標準差平均],1) -> 17 | AN29: =RANK(表格14[[#This Row],[全部負重SN ratio]],表格14[全部負重SN ratio]) -> 27 | AO29: =AVERAGE(表格14[[#This Row],[有負重平均排名]:[全部SN ratio 排名]]) -> 19 | AP29: =RANK(表格14[[#This Row],[綜合排名平均]],表格14[綜合排名平均],1) -> 20
A31: (善用隱藏功能收起部分欄位，及利用第一橫列的排序功能)

Sheet 第一階段測試結果
A1: 含齒輪 | B1: ='original data'!B40 -> 變因 | I1: ='original data'!Q40 -> 測試結果(車子跑動距離)(紅字表示彈簧繩未完全收起) | S1: 等實驗分析後再決定是否要測試這個...
A2: ='original data'!A41 -> 測試組合 | B2: ='original data'!B42 -> 傳動比 | C2: ='original data'!C42 -> 齒輪單雙側傳動給輪子 | D2: ='original data'!E42 -> 齒輪數量 | E2: ='original data'!I42 -> 輪子數 | F2: ='original data'!K42 -> 前輪直徑 | G2: ='original data'!M42 -> 後輪直徑 | H2: ='original data'!P42 -> 輪子厚度 | I2: ='original data'!Q42 -> 負重0g | K2: ='original data'!S42 -> 負重50g | M2: ='original data'!U42 -> 負重100g | O2: ='original data'!W42 -> 負重150g | S2: ='original data'!A74 -> 無齒輪 | T2: ='original data'!B74 -> 變動因子 | W2: ='original data'!E74 -> 測試結果
B3: ='original data'!B41 -> 1 | C3: ='original data'!C41 -> 2 | D3: ='original data'!E41 -> 4 | E3: ='original data'!I41 -> 8 | F3: ='original data'!K41 -> 10 | G3: ='original data'!M41 -> 12 | H3: ='original data'!P41 -> 15 | I3: ='original data'!Q41 -> Y1 | J3: ='original data'!R41 -> Y2 | K3: ='original data'!S41 -> Y3 | L3: ='original data'!T41 -> Y4 | M3: ='original data'!U41 -> Y5 | N3: ='original data'!V41 -> Y6 | O3: ='original data'!W41 -> Y7 | P3: ='original data'!X41 -> Y8 | S3: ='original data'!A75 -> 測試組合 | T3: ='original data'!B76 -> 動力驅動位置 | U3: ='original data'!C76 -> 驅動輪半徑大小 | V3: ='original data'!D76 -> 非驅動輪半徑 | W3: ='original data'!E76 -> 負重0g | Y3: ='original data'!H76 -> 負重50g | AA3: ='original data'!J76 -> 負重100g | AC3: ='original data'!L76 -> 負重150g
A4: ='original data'!A43 -> 1 | B4: ='original data'!B43 -> 1:1 | C4: ='original data'!C43 -> 雙 | D4: ='original data'!E43 -> 3個(前驅) | E4: ='original data'!I43 -> 4輪 | F4: ='original data'!K43 -> 大(45mm) | G4: ='original data'!M43 -> 大(45mm) | H4: ='original data'!P43 -> 單(3.5mm) | I4: ='original data'!Q43 -> 732 | J4: ='original data'!R43 -> 716 | K4: ='original data'!S43 -> 557 | L4: ='original data'!T43 -> 596 | M4: ='original data'!U43 -> 562.2 | N4: ='original data'!V43 -> 500 | O4: ='original data'!W43 -> 526.5 | P4: ='original data'!X43 -> 490 | T4: ='original data'!B75 -> 1 | U4: ='original data'!C75 -> 2 | V4: ='original data'!D75 -> 3 | W4: ='original data'!E75 -> Y1 | X4: ='original data'!F75 -> Y2 | Y4: ='original data'!G75 -> Y3 | Z4: ='original data'!H75 -> Y4 | AA4: ='original data'!I75 -> Y5 | ... AD4: ='original data'!L75 -> Y8
A5: ='original data'!A44 -> 2 | B5: ='original data'!B44 -> 1:1 | C5: ='original data'!C44 -> 雙 | D5: ='original data'!E44 -> 3個(前驅) | E5: ='original data'!I44 -> 3輪 | F5: ='original data'!K44 -> 小(35mm) | G5: ='original data'!M44 -> 小(35mm) | H5: ='original data'!P44 -> 雙(7mm) | I5: ='original data'!Q44 -> 499 | J5: ='original data'!R44 -> 536.5 | K5: ='original data'!S44 -> 540 | L5: ='original data'!T44 -> 499 | M5: ='original data'!U44 -> 481.5 | N5: ='original data'!V44 -> 489 | O5: ='original data'!W44 -> 343 | P5: ='original data'!X44 -> 417 | S5: ='original data'!A77 -> 1 | T5: ='original data'!B77 -> 後輪 | U5: ='original data'!C77 -> 大 | V5: ='original data'!D77 -> 大 | W5: ='original data'!E77 -> 1048 | X5: ='original data'!F77 -> 1072 | Y5: ='original data'!G77 -> 1018 | Z5: ='original data'!H77 -> 808 | ... AD5: ='original data'!L77 -> 660
A6: ='original data'!A45 -> 3 | B6: ='original data'!B45 -> 1:1 | C6: ='original data'!C45 -> 雙 | D6: ='original data'!E45 -> 2個(後驅) | E6: ='original data'!I45 -> 4輪 | F6: ='original data'!K45 -> 大(45mm) | G6: ='original data'!M45 -> 小(35mm) | H6: ='original data'!P45 -> 雙(7mm) | I6: ='original data'!Q45 -> 562 | J6: ='original data'!R45 -> 563.5 | K6: ='original data'!S45 -> 458 | L6: ='original data'!T45 -> 458.5 | M6: ='original data'!U45 -> 531 | N6: ='original data'!V45 -> 484 | O6: ='original data'!W45 -> 495 | P6: ='original data'!X45 -> 430 | S6: ='original data'!A78 -> 2 | T6: ='original data'!B78 -> 後輪 | U6: ='original data'!C78 -> 小 | V6: ='original data'!D78 -> 小 | W6: ='original data'!E78 -> 828 | X6: ='original data'!F78 -> 854 | Y6: ='original data'!G78 -> 840 | Z6: ='original data'!H78 -> 673 | ... AD6: ='original data'!L78 -> 606
A7: ='original data'!A46 -> 4 | B7: ='original data'!B46 -> 1:1 | C7: ='original data'!C46 -> 雙 | D7: ='original data'!E46 -> 2個(後驅) | E7: ='original data'!I46 -> 3輪 | F7: ='original data'!K46 -> 小(35mm) | G7: ='original data'!M46 -> 大(45mm) | H7: ='original data'!P46 -> 單(3.5mm) | I7: ='original data'!Q46 -> 756 | J7: ='original data'!R46 -> 668 | K7: ='original data'!S46 -> 565 | L7: ='original data'!T46 -> 572 | M7: ='original data'!U46 -> 508 | N7: ='original data'!V46 -> 503.5 | O7: ='original data'!W46 -> 489 | P7: ='original data'!X46 -> 387 | S7: ='original data'!A79 -> 3 | T7: ='original data'!B79 -> 前輪 | U7: ='original data'!C79 -> 大 | V7: ='original data'!D79 -> 小 | W7: ='original data'!E79 -> 1188.5 | X7: ='original data'!F79 -> 1140 | Y7: ='original data'!G79 -> 1012 | Z7: ='original data'!H79 -> 783 | ... AD7: ='original data'!L79 -> 601
A8: ='original data'!A47 -> 5 | B8: ='original data'!B47 -> 1:1 | C8: ='original data'!C47 -> 單 | D8: ='original data'!E47 -> 3個(前驅) | E8: ='original data'!I47 -> 4輪 | F8: ='original data'!K47 -> 小(35mm) | G8: ='original data'!M47 -> 大(45mm) | H8: ='original data'!P47 -> 雙(7mm) | I8: ='original data'!Q47 -> 627 | J8: ='original data'!R47 -> 586 | K8: ='original data'!S47 -> 487 | L8: ='original data'!T47 -> 531 | M8: ='original data'!U47 -> 463 | N8: ='original data'!V47 -> 431 | O8: ='original data'!W47 -> 382 | P8: ='original data'!X47 -> 391 | S8: ='original data'!A80 -> 4 | T8: ='original data'!B80 -> 前輪 | U8: ='original data'!C80 -> 小 | V8: ='original data'!D80 -> 大 | W8: ='original data'!E80 -> 1033 | X8: ='original data'!F80 -> 991.5 | Y8: ='original data'!G80 -> 989.5 | Z8: ='original data'!H80 -> 720 | ... AD8: ='original data'!L80 -> 609
A9: ='original data'!A48 -> 6 | B9: ='original data'!B48 -> 1:1 | C9: ='original data'!C48 -> 單 | D9: ='original data'!E48 -> 3個(前驅) | E9: ='original data'!I48 -> 3輪 | F9: ='original data'!K48 -> 大(45mm) | G9: ='original data'!M48 -> 小(35mm) | H9: ='original data'!P48 -> 單(3.5mm) | I9: ='original data'!Q48 -> 756 | J9: ='original data'!T47 -> 531 | K9: ='original data'!S48 -> 625 | L9: ='original data'!T48 -> 723 | M9: ='original data'!U48 -> 570.5 | N9: ='original data'!V48 -> 583 | O9: ='original data'!W48 -> 505 | P9: ='original data'!X48 -> 503
A10: ='original data'!A49 -> 7 | B10: ='original data'!B49 -> 1:1 | C10: ='original data'!C49 -> 單 | D10: ='original data'!E49 -> 2個(後驅) | E10: ='original data'!I49 -> 4輪 | F10: ='original data'!K49 -> 小(35mm) | G10: ='original data'!M49 -> 小(35mm) | H10: ='original data'!P49 -> 單(3.5mm) | I10: ='original data'!Q49 -> 591 | J10: ='original data'!R49 -> 599.5 | K10: ='original data'!S49 -> 529 | L10: ='original data'!T49 -> 495 | M10: ='original data'!U49 -> 523 | N10: ='original data'!V49 -> 501 | O10: ='original data'!W49 -> 456.5 | P10: ='original data'!X49 -> 491
A11: ='original data'!A50 -> 8 | B11: ='original data'!B50 -> 1:1 | C11: ='original data'!C50 -> 單 | D11: ='original data'!E50 -> 2個(後驅) | E11: ='original data'!I50 -> 3輪 | F11: ='original data'!K50 -> 大(45mm) | G11: ='original data'!M50 -> 大(45mm) | H11: ='original data'!P50 -> 雙(7mm) | I11: ='original data'!Q50 -> 762 | J11: ='original data'!R50 -> 772 | K11: ='original data'!S50 -> 634 | L11: ='original data'!T50 -> 632 | M11: ='original data'!U50 -> 577 | N11: ='original data'!V50 -> 577.5 | O11: ='original data'!W50 -> 511.5 | P11: ='original data'!X50 -> 552.5
A12: ='original data'!A51 -> 9 | B12: ='original data'!B51 -> 1:2 | C12: ='original data'!C51 -> 雙 | D12: ='original data'!E51 -> 3個(前驅) | E12: ='original data'!I51 -> 4輪 | F12: ='original data'!K51 -> 大(45mm) | G12: ='original data'!M51 -> 大(45mm) | H12: ='original data'!P51 -> 雙(7mm) | I12: ='original data'!Q51 -> 773 | J12: ='original data'!R51 -> 834 | K12: ='original data'!S51 -> 675 | L12: ='original data'!T51 -> 641 | M12: ='original data'!U51 -> 611 | N12: ='original data'!V51 -> 520 | O12: ='original data'!W51 -> 514 | P12: ='original data'!X51 -> 486
A13: ='original data'!A52 -> 10 | B13: ='original data'!B52 -> 1:2 | C13: ='original data'!C52 -> 雙 | D13: ='original data'!E52 -> 3個(前驅) | E13: ='original data'!I52 -> 3輪 | F13: ='original data'!K52 -> 小(35mm) | G13: ='original data'!M52 -> 小(35mm) | H13: ='original data'!P52 -> 單(3.5mm) | I13: ='original data'!Q52 -> 1088 | J13: ='original data'!R52 -> 983 | K13: ='original data'!S52 -> 967 | L13: ='original data'!T52 -> 943.5 | M13: ='original data'!U52 -> 578 | N13: ='original data'!V52 -> 572 | O13: ='original data'!W52 -> 328 | P13: ='original data'!X52 -> 348.5
A14: ='original data'!A53 -> 11 | B14: ='original data'!B53 -> 1:2 | C14: ='original data'!C53 -> 雙 | D14: ='original data'!E53 -> 2個(後驅) | E14: ='original data'!I53 -> 4輪 | F14: ='original data'!K53 -> 大(45mm) | G14: ='original data'!M53 -> 小(35mm) | H14: ='original data'!P53 -> 單(3.5mm) | I14: ='original data'!Q53 -> 1006 | J14: ='original data'!R53 -> 1124 | K14: ='original data'!S53 -> 1005 | L14: ='original data'!T53 -> 991 | M14: ='original data'!U53 -> 810 | N14: ='original data'!V53 -> 623 | O14: ='original data'!W53 -> 596.5 | P14: ='original data'!X53 -> 618
A15: ='original data'!A54 -> 12 | B15: ='original data'!B54 -> 1:2 | C15: ='original data'!C54 -> 雙 | D15: ='original data'!E54 -> 2個(後驅) | E15: ='original data'!I54 -> 3輪 | F15: ='original data'!K54 -> 小(35mm) | G15: ='original data'!M54 -> 大(45mm) | H15: ='original data'!P54 -> 雙(7mm) | I15: ='original data'!Q54 -> 1337 | J15: ='original data'!R54 -> 1295 | K15: ='original data'!S54 -> 497 | L15: ='original data'!T54 -> 528 | M15: ='original data'!U54 -> 475 | N15: ='original data'!V54 -> 467 | O15: ='original data'!W54 -> 454 | P15: ='original data'!X54 -> 469
A16: ='original data'!A55 -> 13 | B16: ='original data'!B55 -> 1:2 | C16: ='original data'!C55 -> 單 | D16: ='original data'!E55 -> 3個(前驅) | E16: ='original data'!I55 -> 4輪 | F16: ='original data'!K55 -> 小(35mm) | G16: ='original data'!M55 -> 大(45mm) | H16: ='original data'!P55 -> 單(3.5mm) | I16: ='original data'!Q55 -> 763 | J16: ='original data'!R55 -> 817 | K16: ='original data'!S55 -> 594.5 | L16: ='original data'!T55 -> 622 | M16: ='original data'!U55 -> 549 | N16: ='original data'!V55 -> 553 | O16: ='original data'!W55 -> 480 | P16: ='original data'!X55 -> 520
A17: ='original data'!A56 -> 14 | B17: ='original data'!B56 -> 1:2 | C17: ='original data'!C56 -> 單 | D17: ='original data'!E56 -> 3個(前驅) | E17: ='original data'!I56 -> 3輪 | F17: ='original data'!K56 -> 大(45mm) | G17: ='original data'!M56 -> 小(35mm) | H17: ='original data'!P56 -> 雙(7mm) | I17: ='original data'!Q56 -> 825 | J17: ='original data'!R56 -> 908 | K17: ='original data'!S56 -> 1088 | L17: ='original data'!T56 -> 1086 | M17: ='original data'!U56 -> 614 | N17: ='original data'!V56 -> 369 | O17: ='original data'!W56 -> 325 | P17: ='original data'!X56 -> 340
A18: ='original data'!A57 -> 15 | B18: ='original data'!B57 -> 1:2 | C18: ='original data'!C57 -> 單 | D18: ='original data'!E57 -> 2個(後驅) | E18: ='original data'!I57 -> 4輪 | F18: ='original data'!K57 -> 小(35mm) | G18: ='original data'!M57 -> 小(35mm) | H18: ='original data'!P57 -> 雙(7mm) | I18: ='original data'!Q57 -> 945 | J18: ='original data'!R57 -> 1046 | K18: ='original data'!S57 -> 975 | L18: ='original data'!T57 -> 1004 | M18: ='original data'!U57 -> 635 | N18: ='original data'!V57 -> 603.5 | O18: ='original data'!W57 -> 491 | P18: ='original data'!X57 -> 560
A19: ='original data'!A58 -> 16 | B19: ='original data'!B58 -> 1:2 | C19: ='original data'!C58 -> 單 | D19: ='original data'!E58 -> 2個(後驅) | E19: ='original data'!I58 -> 3輪 | F19: ='original data'!K58 -> 大(45mm) | G19: ='original data'!M58 -> 大(45mm) | H19: ='original data'!P58 -> 單(3.5mm) | I19: ='original data'!Q58 -> 1328 | J19: ='original data'!R58 -> 1207 | K19: ='original data'!S58 -> 745 | L19: ='original data'!T58 -> 746 | M19: ='original data'!U58 -> 554 | N19: ='original data'!V58 -> 562 | O19: ='original data'!W58 -> 505 | P19: ='original data'!X58 -> 396
A20: ='original data'!A59 -> 最佳組合 | B20: ='original data'!B59 -> 1:2 | C20: ='original data'!C59 -> 單 | D20: ='original data'!E59 -> 2個(後驅) | E20: ='original data'!I59 -> 4輪 | F20: ='original data'!K59 -> 大(45mm) | G20: ='original data'!M59 -> 大(45mm) | H20: ='original data'!P59 -> 單(3.5mm) | I20: ='original data'!Q59 -> 1127 | J20: ='original data'!R59 -> 1298 | K20: ='original data'!S59 -> 809 | L20: ='original data'!T59 -> 744 | M20: ='original data'!U59 -> 628 | N20: ='original data'!V59 -> 549 | O20: ='original data'!W59 -> 514 | P20: ='original data'!X59 -> 475
A23: 表一有齒輪L16數據
A24: 含齒輪 | B24: 變動因子 | I24: 車子移動距離測試結果(cm)(紅字表示彈簧繩未完全收起) | R24: 平均值(高於平均以橘色標示) | W24: 標準差(低於平均以橘色標示) | AB24: S/N ration(高於平均以橘色表示) | AD24: 完成度(紅色為成功率低) | AE24: 排行(黃色格表示排行前三名) | AK24: 偏移格數
A25: 測試組合 | B25: 傳動比(兩個齒輪尺數差) | C25: 齒輪單雙側傳動給輪子 | D25: 齒輪數量 | E25: 輪子數 | F25: 驅動輪直徑 | G25: 非驅動輪直徑 | H25: 輪子厚度 | I25: 負重0g | L25: 負重50g | N25: 負重100g | P25: 負重150g | R25: 負重0g | S25: 負重50g | T25: 負重100g | U25: 負重150g | V25: 全部平均值 | W25: 負重0g | X25: 負重50g | Y25: 負重100g | Z25: 負重150g | AA25: 全部標準差平均 | AB25: 負重0g | AC25: 全部負重 | AD25: (線有完全收完的比例) | AE25: 負重0g平均值 | AF25: 全部平均值 | AG25: 負重0g標準差 | AH25: 全部標準差平均 | AI25: 完成度 | AJ25: S/N ration
B26: 1 | C26: 2 | D26: 4 | E26: 8 | F26: 10 | G26: 12 | H26: 15 | I26: Y1 | J26: Y2 | K26: Y3 | L26: Y4 | M26: Y5 | N26: Y6 | O26: Y7 | P26: Y8 | Q26: Y9
A27: 1 | B27: 1:1 | C27: 雙 | D27: 3個 | E27: 4輪 | F27: 大(45mm) | G27: 大(45mm) | H27: 單(3.5mm) | I27: 732 | J27: 716 | K27: 632 | L27: 557 | M27: 596 | N27: 562.2 | O27: 500 | P27: 526.5 | Q27: 490 | R27: =AVERAGE(I27,J27,K27) -> 693.33333 | S27: =AVERAGE(L27,M27) -> 576.5 | T27: =AVERAGE(N27,O27) -> 531.1 | U27: =AVERAGE(P27,Q27) -> 508.25 | V27: =AVERAGE(I27:Q27) -> 590.18889 | W27: =_xlfn.STDEV.S(I27,J27,K27) -> 53.715299 | X27: =_xlfn.STDEV.S(L27,M27) -> 27.577164 | Y27: =_xlfn.STDEV.S(N27,O27) -> 43.982042 | Z27: =_xlfn.STDEV.S(P27,Q27) -> 25.809398 | AA27: =AVERAGE(W27:Z27) -> 37.770976 | AB27: =-10*LOG10(1/3*((1/$I27)^2+(1/$J27)^2+(1/$K27)^2)) -> 56.763688 | AC27: =-10*LOG10(1/9*((1/$I27)^2+(1/$J27)^2+(1/$K27)^2+(1/$L27)^2+(1/$M27)^2+(1/$N27)^2+(1/$O27)^2+(1/$P27)^2+(1/$Q27)^2)) -> 55.181563 | AD27: 0.33333333 | AE27: =RANK(R27,R$27:R$43) -> 12 | AF27: =RANK(V27,V$27:V$43) -> 12 | AG27: =RANK(W27,W$27:W$43) -> 8 | AH27: =RANK(AA27,AA$27:AA$43,1) -> 10 | AI27: =RANK(AD27,AD$27:AD$43) -> 9 | AJ27: =RANK(AC27,AC$27:AC$43) -> 9 | AM27: 10 | AN27: 10 | AO27: 15 | AP27: 5 | AQ27: 2 | AR27: 2 | AS27: 2 | AT27: 2 | AU27: 2
A28: 2 | B28: 1:1 | C28: 雙 | D28: 3個 | E28: 3輪 | F28: 小(35mm) | G28: 小(35mm) | H28: 雙(7mm) | I28: 499 | J28: 536.5 | K28: 506.5 | L28: 540 | M28: 499 | N28: 481.5 | O28: 489 | P28: 343 | Q28: 417 | R28: =AVERAGE(I28,J28,K28) -> 514 | S28: =AVERAGE(L28,M28) -> 519.5 | T28: =AVERAGE(N28,O28) -> 485.25 | U28: =AVERAGE(P28,Q28) -> 380 | V28: =AVERAGE(I28:Q28) -> 479.05556 | W28: =_xlfn.STDEV.S(I28,J28,K28) -> 19.843135 | X28: =_xlfn.STDEV.S(L28,M28) -> 28.991378 | Y28: =_xlfn.STDEV.S(N28,O28) -> 5.3033009 | Z28: =_xlfn.STDEV.S(P28,Q28) -> 52.325902 | AA28: =AVERAGE(W28:Z28) -> 26.615929 | AB28: =-10*LOG10(1/3*((1/$I28)^2+(1/$J28)^2+(1/$K28)^2)) -> 54.206628 | AC28: =-10*LOG10(1/9*((1/$I28)^2+(1/$J28)^2+(1/$K28)^2+(1/$L28)^2+(1/$M28)^2+(1/$N28)^2+(1/$O28)^2+(1/$P28)^2+(1/$Q28)^2)) -> 53.353621 | AD28: 0.33333333 | AE28: =RANK(R28,R$27:R$43) -> 17 | AF28: =RANK(V28,V$27:V$43) -> 17 | AG28: =RANK(W28,W$27:W$43) -> 15 | AH28: =RANK(AA28,AA$27:AA$43,1) -> 6 | AI28: =RANK(AD28,AD$27:AD$43) -> 9 | AJ28: =RANK(AC28,AC$27:AC$43) -> 17 | AM28: 10 | AN28: 2 | AO28: 10 | AP28: 2 | AQ28: 5 | AR28: 5 | AS28: 5 | AT28: 2 | AU28: 2
A29: 3 | B29: 1:1 | C29: 雙 | D29: 2個 | E29: 4輪 | F29: 小(35mm) | G29: 大(45mm) | H29: 雙(7mm) | I29: 562 | J29: 563.5 | K29: 502 | L29: 458 | M29: 458.5 | N29: 531 | O29: 484 | P29: 495 | Q29: 430 | R29: =AVERAGE(I29,J29,K29) -> 542.5 | S29: =AVERAGE(L29,M29) -> 458.25 | T29: =AVERAGE(N29,O29) -> 507.5 | U29: =AVERAGE(P29,Q29) -> 462.5 | V29: =AVERAGE(I29:Q29) -> 498.22222 | W29: =_xlfn.STDEV.S(I29,J29,K29) -> 35.082047 | X29: =_xlfn.STDEV.S(L29,M29) -> 0.35355339 | Y29: =_xlfn.STDEV.S(N29,O29) -> 33.234019 | Z29: =_xlfn.STDEV.S(P29,Q29) -> 45.961941 | AA29: =AVERAGE(W29:Z29) -> 28.65789 | AB29: =-10*LOG10(1/3*((1/$I29)^2+(1/$J29)^2+(1/$K29)^2)) -> 54.649762 | AC29: =-10*LOG10(1/9*((1/$I29)^2+(1/$J29)^2+(1/$K29)^2+(1/$L29)^2+(1/$M29)^2+(1/$N29)^2+(1/$O29)^2+(1/$P29)^2+(1/$Q29)^2)) -> 53.8472 | AD29: 0.88888889 | AE29: =RANK(R29,R$27:R$43) -> 16 | AF29: =RANK(V29,V$27:V$43) -> 16 | AG29: =RANK(W29,W$27:W$43) -> 12 | AH29: =RANK(AA29,AA$27:AA$43,1) -> 7 | AI29: =RANK(AD29,AD$27:AD$43) -> 1 | AJ29: =RANK(AC29,AC$27:AC$43) -> 15 | AM29: 10 | AN29: 10 | AO29: 5 | AP29: 5 | AQ29: 5 | AR29: 5 | AS29: 2 | AT29: 2 | AU29: 2
A30: 4 | B30: 1:1 | C30: 雙 | D30: 2個 | E30: 3輪 | F30: 大(45mm) | G30: 小(35mm) | H30: 單(3.5mm) | I30: 756 | J30: 668 | K30: 702.5 | L30: 565 | M30: 572 | N30: 508 | O30: 503.5 | P30: 489 | Q30: 387 | R30: =AVERAGE(I30,J30,K30) -> 708.83333 | S30: =AVERAGE(L30,M30) -> 568.5 | T30: =AVERAGE(N30,O30) -> 505.75 | U30: =AVERAGE(P30,Q30) -> 438 | V30: =AVERAGE(I30:Q30) -> 572.33333 | W30: =_xlfn.STDEV.S(I30,J30,K30) -> 44.340538 | X30: =_xlfn.STDEV.S(L30,M30) -> 4.9497475 | Y30: =_xlfn.STDEV.S(N30,O30) -> 3.1819805 | Z30: =_xlfn.STDEV.S(P30,Q30) -> 72.124892 | AA30: =AVERAGE(W30:Z30) -> 31.149289 | AB30: =-10*LOG10(1/3*((1/$I30)^2+(1/$J30)^2+(1/$K30)^2)) -> 56.977402 | AC30: =-10*LOG10(1/9*((1/$I30)^2+(1/$J30)^2+(1/$K30)^2+(1/$L30)^2+(1/$M30)^2+(1/$N30)^2+(1/$O30)^2+(1/$P30)^2+(1/$Q30)^2)) -> 54.645018 | AD30: 0.33333333 | AE30: =RANK(R30,R$27:R$43) -> 11 | AF30: =RANK(V30,V$27:V$43) -> 13 | AG30: =RANK(W30,W$27:W$43) -> 10 | AH30: =RANK(AA30,AA$27:AA$43,1) -> 8 | AI30: =RANK(AD30,AD$27:AD$43) -> 9 | AJ30: =RANK(AC30,AC$27:AC$43) -> 12 | AM30: 15 | AN30: 10 | AO30: 15 | AP30: 5 | AQ30: 10 | AR30: 5 | AS30: 2 | AT30: 2 | AU30: 2
A31: 5 | B31: 1:1 | C31: 單 | D31: 3個 | E31: 4輪 | F31: 小(35mm) | G31: 大(45mm) | H31: 雙(7mm) | I31: 627 | J31: 586 | K31: 600 | L31: 487 | M31: 531 | N31: 463 | O31: 431 | P31: 382 | Q31: 391 | R31: =AVERAGE(I31,J31,K31) -> 604.33333 | S31: =AVERAGE(L31,M31) -> 509 | T31: =AVERAGE(N31,O31) -> 447 | U31: =AVERAGE(P31,Q31) -> 386.5 | V31: =AVERAGE(I31:Q31) -> 499.77778 | W31: =_xlfn.STDEV.S(I31,J31,K31) -> 20.840665 | X31: =_xlfn.STDEV.S(L31,M31) -> 31.112698 | Y31: =_xlfn.STDEV.S(N31,O31) -> 22.627417 | Z31: =_xlfn.STDEV.S(P31,Q31) -> 6.363961 | AA31: =AVERAGE(W31:Z31) -> 20.236185 | AB31: =-10*LOG10(1/3*((1/$I31)^2+(1/$J31)^2+(1/$K31)^2)) -> 55.615335 | AC31: =-10*LOG10(1/9*((1/$I31)^2+(1/$J31)^2+(1/$K31)^2+(1/$L31)^2+(1/$M31)^2+(1/$N31)^2+(1/$O31)^2+(1/$P31)^2+(1/$Q31)^2)) -> 53.583212 | AD31: 0.66666667 | AE31: =RANK(R31,R$27:R$43) -> 14 | AF31: =RANK(V31,V$27:V$43) -> 15 | AG31: =RANK(W31,W$27:W$43) -> 14 | AH31: =RANK(AA31,AA$27:AA$43,1) -> 4 | AI31: =RANK(AD31,AD$27:AD$43) -> 2 | AJ31: =RANK(AC31,AC$27:AC$43) -> 16 | AM31: 40 | AN31: 20 | AO31: 30 | AP31: 20 | AQ31: 10 | AR31: 10 | AS31: 5 | AT31: 5 | AU31: 2
A32: 6 | B32: 1:1 | C32: 單 | D32: 3個 | E32: 3輪 | F32: 大(45mm) | G32: 小(35mm) | H32: 單(3.5mm) | I32: 756 | J32: 531 | K32: 720 | L32: 625 | M32: 723 | N32: 570.5 | O32: 583 | P32: 505 | Q32: 503 | R32: =AVERAGE(I32,J32,K32) -> 669 | S32: =AVERAGE(L32,M32) -> 674 | T32: =AVERAGE(N32,O32) -> 576.75 | U32: =AVERAGE(P32,Q32) -> 504 | V32: =AVERAGE(I32:Q32) -> 612.94444 | W32: =_xlfn.STDEV.S(I32,J32,K32) -> 120.85942 | X32: =_xlfn.STDEV.S(L32,M32) -> 69.296465 | Y32: =_xlfn.STDEV.S(N32,O32) -> 8.8388348 | Z32: =_xlfn.STDEV.S(P32,Q32) -> 1.4142136 | AA32: =AVERAGE(W32:Z32) -> 50.102234 | AB32: =-10*LOG10(1/3*((1/$I32)^2+(1/$J32)^2+(1/$K32)^2)) -> 56.18267 | AC32: =-10*LOG10(1/9*((1/$I32)^2+(1/$J32)^2+(1/$K32)^2+(1/$L32)^2+(1/$M32)^2+(1/$N32)^2+(1/$O32)^2+(1/$P32)^2+(1/$Q32)^2)) -> 55.46231 | AD32: 0.66666667 | AE32: =RANK(R32,R$27:R$43) -> 13 | AF32: =RANK(V32,V$27:V$43) -> 11 | AG32: =RANK(W32,W$27:W$43) -> 5 | AH32: =RANK(AA32,AA$27:AA$43,1) -> 12 | AI32: =RANK(AD32,AD$27:AD$43) -> 2 | AJ32: =RANK(AC32,AC$27:AC$43) -> 8 | AK32: 空車超過兩格歪斜 | AM32: 80 | AN32: 70 | AO32: 70 | AP32: 20 | AQ32: 40 | AR32: 10 | AS32: 10 | AT32: 5 | AU32: 2
A33: 7 | B33: 1:1 | C33: 單 | D33: 2個 | E33: 4輪 | F33: 小(35mm) | G33: 小(35mm) | H33: 單(3.5mm) | I33: 591 | J33: 599.5 | K33: 583 | L33: 529 | M33: 495 | N33: 523 | O33: 501 | P33: 456.5 | Q33: 491 | R33: =AVERAGE(I33,J33,K33) -> 591.16667 | S33: =AVERAGE(L33,M33) -> 512 | T33: =AVERAGE(N33,O33) -> 512 | U33: =AVERAGE(P33,Q33) -> 473.75 | V33: =AVERAGE(I33:Q33) -> 529.88889 | W33: =_xlfn.STDEV.S(I33,J33,K33) -> 8.2512625 | X33: =_xlfn.STDEV.S(L33,M33) -> 24.041631 | Y33: =_xlfn.STDEV.S(N33,O33) -> 15.556349 | Z33: =_xlfn.STDEV.S(P33,Q33) -> 24.395184 | AA33: =AVERAGE(W33:Z33) -> 18.061107 | AB33: =-10*LOG10(1/3*((1/$I33)^2+(1/$J33)^2+(1/$K33)^2)) -> 55.432507 | AC33: =-10*LOG10(1/9*((1/$I33)^2+(1/$J33)^2+(1/$K33)^2+(1/$L33)^2+(1/$M33)^2+(1/$N33)^2+(1/$O33)^2+(1/$P33)^2+(1/$Q33)^2)) -> 54.379869 | AD33: 0.66666667 | AE33: =RANK(R33,R$27:R$43) -> 15 | AF33: =RANK(V33,V$27:V$43) -> 14 | AG33: =RANK(W33,W$27:W$43) -> 17 | AH33: =RANK(AA33,AA$27:AA$43,1) -> 2 | AI33: =RANK(AD33,AD$27:AD$43) -> 2 | AJ33: =RANK(AC33,AC$27:AC$43) -> 13 | AM33: 40 | AN33: 30 | AO33: 60 | AP33: 20 | AQ33: 20 | AR33: 20 | AS33: 10 | AT33: 10 | AU33: 5
A34: 8 | B34: 1:1 | C34: 單 | D34: 2個 | E34: 3輪 | F34: 大(45mm) | G34: 大(45mm) | H34: 雙(7mm) | I34: 762 | J34: 772 | K34: 743 | L34: 634 | M34: 632 | N34: 577 | O34: 577.5 | P34: 511.5 | Q34: 552.5 | R34: =AVERAGE(I34,J34,K34) -> 759 | S34: =AVERAGE(L34,M34) -> 633 | T34: =AVERAGE(N34,O34) -> 577.25 | U34: =AVERAGE(P34,Q34) -> 532 | V34: =AVERAGE(I34:Q34) -> 640.16667 | W34: =_xlfn.STDEV.S(I34,J34,K34) -> 14.73092 | X34: =_xlfn.STDEV.S(L34,M34) -> 1.4142136 | Y34: =_xlfn.STDEV.S(N34,O34) -> 0.35355339 | Z34: =_xlfn.STDEV.S(P34,Q34) -> 28.991378 | AA34: =AVERAGE(W34:Z34) -> 11.372516 | AB34: =-10*LOG10(1/3*((1/$I34)^2+(1/$J34)^2+(1/$K34)^2)) -> 57.601538 | AC34: =-10*LOG10(1/9*((1/$I34)^2+(1/$J34)^2+(1/$K34)^2+(1/$L34)^2+(1/$M34)^2+(1/$N34)^2+(1/$O34)^2+(1/$P34)^2+(1/$Q34)^2)) -> 55.868273 | AD34: 0.55555556 | AE34: =RANK(R34,R$27:R$43) -> 10 | AF34: =RANK(V34,V$27:V$43) -> 9 | AG34: =RANK(W34,W$27:W$43) -> 16 | AH34: =RANK(AA34,AA$27:AA$43,1) -> 1 | AI34: =RANK(AD34,AD$27:AD$43) -> 5 | AJ34: =RANK(AC34,AC$27:AC$43) -> 5 | AM34: 40 | AN34: 30 | AO34: 40 | AP34: 12 | AQ34: 10 | AR34: 5 | AS34: 5 | AT34: 2 | AU34: 2
A35: 9 | B35: 1:2 | C35: 雙 | D35: 3個 | E35: 4輪 | F35: 大(45mm) | G35: 大(45mm) | H35: 雙(7mm) | I35: 773 | J35: 834 | K35: 858 | L35: 675 | M35: 641 | N35: 611 | O35: 520 | P35: 514 | Q35: 486 | R35: =AVERAGE(I35,J35,K35) -> 821.66667 | S35: =AVERAGE(L35,M35) -> 658 | T35: =AVERAGE(N35,O35) -> 565.5 | U35: =AVERAGE(P35,Q35) -> 500 | V35: =AVERAGE(I35:Q35) -> 656.88889 | W35: =_xlfn.STDEV.S(I35,J35,K35) -> 43.821608 | X35: =_xlfn.STDEV.S(L35,M35) -> 24.041631 | Y35: =_xlfn.STDEV.S(N35,O35) -> 64.346717 | Z35: =_xlfn.STDEV.S(P35,Q35) -> 19.79899 | AA35: =AVERAGE(W35:Z35) -> 38.002236 | AB35: =-10*LOG10(1/3*((1/$I35)^2+(1/$J35)^2+(1/$K35)^2)) -> 58.268477 | AC35: =-10*LOG10(1/9*((1/$I35)^2+(1/$J35)^2+(1/$K35)^2+(1/$L35)^2+(1/$M35)^2+(1/$N35)^2+(1/$O35)^2+(1/$P35)^2+(1/$Q35)^2)) -> 55.832863 | AD35: 0 | AE35: =RANK(R35,R$27:R$43) -> 8 | AF35: =RANK(V35,V$27:V$43) -> 8 | AG35: =RANK(W35,W$27:W$43) -> 11 | AH35: =RANK(AA35,AA$27:AA$43,1) -> 11 | AI35: =RANK(AD35,AD$27:AD$43) -> 16 | AJ35: =RANK(AC35,AC$27:AC$43) -> 6 | AM35: 20 | AN35: 20 | AO35: 20 | AP35: 10 | AQ35: 2 | AR35: 2 | AS35: 2 | AT35: 2 | AU35: 2
A36: 10 | B36: 1:2 | C36: 雙 | D36: 3個 | E36: 3輪 | F36: 小(35mm) | G36: 小(35mm) | H36: 單(3.5mm) | I36: 1088 | J36: 983 | K36: 1010 | L36: 967 | M36: 943.5 | N36: 578 | O36: 572 | P36: 328 | Q36: 348.5 | R36: =AVERAGE(I36,J36,K36) -> 1027 | S36: =AVERAGE(L36,M36) -> 955.25 | T36: =AVERAGE(N36,O36) -> 575 | U36: =AVERAGE(P36,Q36) -> 338.25 | V36: =AVERAGE(I36:Q36) -> 757.55556 | W36: =_xlfn.STDEV.S(I36,J36,K36) -> 54.525224 | X36: =_xlfn.STDEV.S(L36,M36) -> 16.617009 | Y36: =_xlfn.STDEV.S(N36,O36) -> 4.2426407 | Z36: =_xlfn.STDEV.S(P36,Q36) -> 14.495689 | AA36: =AVERAGE(W36:Z36) -> 22.470141 | AB36: =-10*LOG10(1/3*((1/$I36)^2+(1/$J36)^2+(1/$K36)^2)) -> 60.207612 | AC36: =-10*LOG10(1/9*((1/$I36)^2+(1/$J36)^2+(1/$K36)^2+(1/$L36)^2+(1/$M36)^2+(1/$N36)^2+(1/$O36)^2+(1/$P36)^2+(1/$Q36)^2)) -> 54.974041 | AD36: 0.55555556 | AE36: =RANK(R36,R$27:R$43) -> 5 | AF36: =RANK(V36,V$27:V$43) -> 5 | AG36: =RANK(W36,W$27:W$43) -> 7 | AH36: =RANK(AA36,AA$27:AA$43,1) -> 5 | AI36: =RANK(AD36,AD$27:AD$43) -> 5 | AJ36: =RANK(AC36,AC$27:AC$43) -> 11 | AM36: 20 | AN36: 20 | AO36: 20 | AP36: 10 | AQ36: 5 | AR36: 5 | AS36: 2 | AT36: 2 | AU36: 2
A37: 11 | B37: 1:2 | C37: 雙 | D37: 2個 | E37: 4輪 | F37: 小(35mm) | G37: 大(45mm) | H37: 單(3.5mm) | I37: 1006 | J37: 1124 | K37: 1132 | L37: 1005 | M37: 991 | N37: 810 | O37: 623 | P37: 596.5 | Q37: 618 | R37: =AVERAGE(I37,J37,K37) -> 1087.3333 | S37: =AVERAGE(L37,M37) -> 998 | T37: =AVERAGE(N37,O37) -> 716.5 | U37: =AVERAGE(P37,Q37) -> 607.25 | V37: =AVERAGE(I37:Q37) -> 878.38889 | W37: =_xlfn.STDEV.S(I37,J37,K37) -> 70.550219 | X37: =_xlfn.STDEV.S(L37,M37) -> 9.8994949 | Y37: =_xlfn.STDEV.S(N37,O37) -> 132.22897 | Z37: =_xlfn.STDEV.S(P37,Q37) -> 15.202796 | AA37: =AVERAGE(W37:Z37) -> 56.970369 | AB37: =-10*LOG10(1/3*((1/$I37)^2+(1/$J37)^2+(1/$K37)^2)) -> 60.688781 | AC37: =-10*LOG10(1/9*((1/$I37)^2+(1/$J37)^2+(1/$K37)^2+(1/$L37)^2+(1/$M37)^2+(1/$N37)^2+(1/$O37)^2+(1/$P37)^2+(1/$Q37)^2)) -> 58.050926 | AD37: 0.55555556 | AE37: =RANK(R37,R$27:R$43) -> 4 | AF37: =RANK(V37,V$27:V$43) -> 1 | AG37: =RANK(W37,W$27:W$43) -> 6 | AH37: =RANK(AA37,AA$27:AA$43,1) -> 14 | AI37: =RANK(AD37,AD$27:AD$43) -> 5 | AJ37: =RANK(AC37,AC$27:AC$43) -> 1 | AM37: 25 | AN37: 10 | AO37: 20 | AP37: 10 | AQ37: 5 | AR37: 5 | AS37: 5 | AT37: 5 | AU37: 5
A38: 12 | B38: 1:2 | C38: 雙 | D38: 2個 | E38: 3輪 | F38: 大(45mm) | G38: 小(35mm) | H38: 雙(7mm) | I38: 1337 | J38: 1295 | K38: 989 | L38: 497 | M38: 528 | N38: 475 | O38: 467 | P38: 454 | Q38: 469 | R38: =AVERAGE(I38,J38,K38) -> 1207 | S38: =AVERAGE(L38,M38) -> 512.5 | T38: =AVERAGE(N38,O38) -> 471 | U38: =AVERAGE(P38,Q38) -> 461.5 | V38: =AVERAGE(I38:Q38) -> 723.44444 | W38: =_xlfn.STDEV.S(I38,J38,K38) -> 189.95789 | X38: =_xlfn.STDEV.S(L38,M38) -> 21.92031 | Y38: =_xlfn.STDEV.S(N38,O38) -> 5.6568542 | Z38: =_xlfn.STDEV.S(P38,Q38) -> 10.606602 | AA38: =AVERAGE(W38:Z38) -> 57.035414 | AB38: =-10*LOG10(1/3*((1/$I38)^2+(1/$J38)^2+(1/$K38)^2)) -> 61.390471 | AC38: =-10*LOG10(1/9*((1/$I38)^2+(1/$J38)^2+(1/$K38)^2+(1/$L38)^2+(1/$M38)^2+(1/$N38)^2+(1/$O38)^2+(1/$P38)^2+(1/$Q38)^2)) -> 55.035495 | AD38: 0.22222222 | AE38: =RANK(R38,R$27:R$43) -> 1 | AF38: =RANK(V38,V$27:V$43) -> 7 | AG38: =RANK(W38,W$27:W$43) -> 2 | AH38: =RANK(AA38,AA$27:AA$43,1) -> 15 | AI38: =RANK(AD38,AD$27:AD$43) -> 14 | AJ38: =RANK(AC38,AC$27:AC$43) -> 10 | AM38: 10 | AN38: 10 | AO38: 10 | AP38: 5 | AQ38: 5 | AR38: 5 | AS38: 2 | AT38: 5 | AU38: 2
